<sdf version='1.6'>
  <world name='default'>
    <light name='sun' type='directional'>
      <cast_shadows>1</cast_shadows>
      <pose frame=''>0 0 10 0 -0 0</pose>
      <diffuse>0.8 0.8 0.8 1</diffuse>
      <specular>0.1 0.1 0.1 1</specular>
      <attenuation>
        <range>1000</range>
        <constant>0.9</constant>
        <linear>0.01</linear>
        <quadratic>0.001</quadratic>
      </attenuation>
      <direction>-0.5 0.5 -1</direction>
    </light>
    <model name='ground_plane'>
      <static>1</static>
      <link name='link'>
        <collision name='collision'>
          <geometry>
            <plane>
              <normal>0 0 1</normal>
              <size>100 100</size>
            </plane>
          </geometry>
          <surface>
            <friction>
              <ode>
                <mu>100</mu>
                <mu2>50</mu2>
              </ode>
              <torsional>
                <ode/>
              </torsional>
            </friction>
            <contact>
              <ode/>
            </contact>
            <bounce/>
          </surface>
          <max_contacts>10</max_contacts>
        </collision>
        <visual name='visual'>
          <cast_shadows>0</cast_shadows>
          <geometry>
            <plane>
              <normal>0 0 1</normal>
              <size>100 100</size>
            </plane>
          </geometry>
          <material>
            <script>
              <uri>file://media/materials/scripts/gazebo.material</uri>
              <name>Gazebo/Grey</name>
            </script>
          </material>
        </visual>
        <self_collide>0</self_collide>
        <kinematic>0</kinematic>
        <gravity>1</gravity>
      </link>
    </model>
    <gravity>0 0 -9.8</gravity>
    <magnetic_field>6e-06 2.3e-05 -4.2e-05</magnetic_field>
    <atmosphere type='adiabatic'/>
    <physics name='default_physics' default='0' type='ode'>
      <max_step_size>0.001</max_step_size>
      <real_time_factor>1</real_time_factor>
      <real_time_update_rate>1000</real_time_update_rate>
    </physics>
    <scene>
      <ambient>0.4 0.4 0.4 1</ambient>
      <background>0.7 0.7 0.7 1</background>
      <shadows>1</shadows>
    </scene>
    <spherical_coordinates>
      <surface_model>EARTH_WGS84</surface_model>
      <latitude_deg>0</latitude_deg>
      <longitude_deg>0</longitude_deg>
      <elevation>0</elevation>
      <heading_deg>0</heading_deg>
    </spherical_coordinates>
    <model name='Untitled'>
      <pose frame=''>-3.2765 -0.725 0 0 -0 0</pose>
      <link name='Wall_3'>
        <collision name='Wall_3_Collision'>
          <geometry>
            <box>
              <size>8 0.15 2.5</size>
            </box>
          </geometry>
          <pose frame=''>0 0 1.25 0 -0 0</pose>
          <max_contacts>10</max_contacts>
          <surface>
            <contact>
              <ode/>
            </contact>
            <bounce/>
            <friction>
              <torsional>
                <ode/>
              </torsional>
              <ode/>
            </friction>
          </surface>
        </collision>
        <visual name='Wall_3_Visual'>
          <pose frame=''>0 0 1.25 0 -0 0</pose>
          <geometry>
            <box>
              <size>8 0.15 2.5</size>
            </box>
          </geometry>
          <material>
            <script>
              <uri>file://media/materials/scripts/gazebo.material</uri>
              <name>Gazebo/Grey</name>
            </script>
            <ambient>1 0.764706 0.305882 1</ambient>
          </material>
        </visual>
        <pose frame=''>2.25 2.675 0 0 -0 0</pose>
        <self_collide>0</self_collide>
        <kinematic>0</kinematic>
        <gravity>1</gravity>
      </link>
      <link name='Wall_4'>
        <pose frame=''>6.175 0 0 0 0 -1.5708</pose>
        <visual name='Wall_4_Visual_0'>
          <pose frame=''>-1.52338 0 1.25 0 -0 0</pose>
          <geometry>
            <box>
              <size>2.45325 0.15 2.5</size>
            </box>
          </geometry>
          <material>
            <script>
              <uri>file://media/materials/scripts/gazebo.material</uri>
              <name>Gazebo/Grey</name>
            </script>
            <ambient>0.435294 0.796078 0.67451 1</ambient>
          </material>
        </visual>
        <collision name='Wall_4_Collision_0'>
          <geometry>
            <box>
              <size>2.45325 0.15 2.5</size>
            </box>
          </geometry>
          <pose frame=''>-1.52338 0 1.25 0 -0 0</pose>
          <max_contacts>10</max_contacts>
          <surface>
            <contact>
              <ode/>
            </contact>
            <bounce/>
            <friction>
              <torsional>
                <ode/>
              </torsional>
              <ode/>
            </friction>
          </surface>
        </collision>
        <visual name='Wall_4_Visual_1'>
          <pose frame=''>1.22662 0 0.25 0 -0 0</pose>
          <geometry>
            <box>
              <size>3.04675 0.15 0.5</size>
            </box>
          </geometry>
          <material>
            <script>
              <uri>file://media/materials/scripts/gazebo.material</uri>
              <name>Gazebo/Grey</name>
            </script>
            <ambient>0.435294 0.796078 0.67451 1</ambient>
          </material>
        </visual>
        <collision name='Wall_4_Collision_1'>
          <geometry>
            <box>
              <size>3.04675 0.15 0.5</size>
            </box>
          </geometry>
          <pose frame=''>1.22662 0 0.25 0 -0 0</pose>
          <max_contacts>10</max_contacts>
          <surface>
            <contact>
              <ode/>
            </contact>
            <bounce/>
            <friction>
              <torsional>
                <ode/>
              </torsional>
              <ode/>
            </friction>
          </surface>
        </collision>
        <visual name='Wall_4_Visual_2'>
          <pose frame=''>1.62662 0 1.5 0 -0 0</pose>
          <geometry>
            <box>
              <size>2.24675 0.15 2</size>
            </box>
          </geometry>
          <material>
            <script>
              <uri>file://media/materials/scripts/gazebo.material</uri>
              <name>Gazebo/Grey</name>
            </script>
            <ambient>0.435294 0.796078 0.67451 1</ambient>
          </material>
        </visual>
        <collision name='Wall_4_Collision_2'>
          <geometry>
            <box>
              <size>2.24675 0.15 2</size>
            </box>
          </geometry>
          <pose frame=''>1.62662 0 1.5 0 -0 0</pose>
          <max_contacts>10</max_contacts>
          <surface>
            <contact>
              <ode/>
            </contact>
            <bounce/>
            <friction>
              <torsional>
                <ode/>
              </torsional>
              <ode/>
            </friction>
          </surface>
        </collision>
        <visual name='Wall_4_Visual_3'>
          <pose frame=''>0.103248 0 1.9 0 -0 0</pose>
          <geometry>
            <box>
              <size>0.8 0.15 1.2</size>
            </box>
          </geometry>
          <material>
            <script>
              <uri>file://media/materials/scripts/gazebo.material</uri>
              <name>Gazebo/Grey</name>
            </script>
            <ambient>0.435294 0.796078 0.67451 1</ambient>
          </material>
        </visual>
        <collision name='Wall_4_Collision_3'>
          <geometry>
            <box>
              <size>0.8 0.15 1.2</size>
            </box>
          </geometry>
          <pose frame=''>0.103248 0 1.9 0 -0 0</pose>
          <max_contacts>10</max_contacts>
          <surface>
            <contact>
              <ode/>
            </contact>
            <bounce/>
            <friction>
              <torsional>
                <ode/>
              </torsional>
              <ode/>
            </friction>
          </surface>
        </collision>
        <self_collide>0</self_collide>
        <kinematic>0</kinematic>
        <gravity>1</gravity>
      </link>
      <link name='Wall_5'>
        <pose frame=''>0 -2.675 0 0 -0 3.14159</pose>
        <visual name='Wall_5_Visual_0'>
          <pose frame=''>-1.24628 0 1.25 0 -0 0</pose>
          <geometry>
            <box>
              <size>10.0074 0.15 2.5</size>
            </box>
          </geometry>
          <material>
            <script>
              <uri>file://media/materials/scripts/gazebo.material</uri>
              <name>Gazebo/Grey</name>
            </script>
            <ambient>0.760784 0.662745 0.627451 1</ambient>
          </material>
        </visual>
        <collision name='Wall_5_Collision_0'>
          <geometry>
            <box>
              <size>10.0074 0.15 2.5</size>
            </box>
          </geometry>
          <pose frame=''>-1.24628 0 1.25 0 -0 0</pose>
          <max_contacts>10</max_contacts>
          <surface>
            <contact>
              <ode/>
            </contact>
            <bounce/>
            <friction>
              <torsional>
                <ode/>
              </torsional>
              <ode/>
            </friction>
          </surface>
        </collision>
        <visual name='Wall_5_Visual_1'>
          <pose frame=''>5.45372 0 1.25 0 -0 0</pose>
          <geometry>
            <box>
              <size>1.59257 0.15 2.5</size>
            </box>
          </geometry>
          <material>
            <script>
              <uri>file://media/materials/scripts/gazebo.material</uri>
              <name>Gazebo/Grey</name>
            </script>
            <ambient>0.760784 0.662745 0.627451 1</ambient>
          </material>
        </visual>
        <collision name='Wall_5_Collision_1'>
          <geometry>
            <box>
              <size>1.59257 0.15 2.5</size>
            </box>
          </geometry>
          <pose frame=''>5.45372 0 1.25 0 -0 0</pose>
          <max_contacts>10</max_contacts>
          <surface>
            <contact>
              <ode/>
            </contact>
            <bounce/>
            <friction>
              <torsional>
                <ode/>
              </torsional>
              <ode/>
            </friction>
          </surface>
        </collision>
        <visual name='Wall_5_Visual_2'>
          <pose frame=''>4.20744 0 2.25 0 -0 0</pose>
          <geometry>
            <box>
              <size>0.9 0.15 0.5</size>
            </box>
          </geometry>
          <material>
            <script>
              <uri>file://media/materials/scripts/gazebo.material</uri>
              <name>Gazebo/Grey</name>
            </script>
            <ambient>0.760784 0.662745 0.627451 1</ambient>
          </material>
        </visual>
        <collision name='Wall_5_Collision_2'>
          <geometry>
            <box>
              <size>0.9 0.15 0.5</size>
            </box>
          </geometry>
          <pose frame=''>4.20744 0 2.25 0 -0 0</pose>
          <max_contacts>10</max_contacts>
          <surface>
            <contact>
              <ode/>
            </contact>
            <bounce/>
            <friction>
              <torsional>
                <ode/>
              </torsional>
              <ode/>
            </friction>
          </surface>
        </collision>
        <self_collide>0</self_collide>
        <kinematic>0</kinematic>
        <gravity>1</gravity>
      </link>
      <link name='Wall_6'>
        <pose frame=''>-6.175 0 0 0 -0 1.5708</pose>
        <visual name='Wall_6_Visual_0'>
          <pose frame=''>-1.58672 0 1.25 0 -0 0</pose>
          <geometry>
            <box>
              <size>2.32655 0.15 2.5</size>
            </box>
          </geometry>
          <material>
            <script>
              <uri>file://media/materials/scripts/gazebo.material</uri>
              <name>Gazebo/Grey</name>
            </script>
            <ambient>0.435294 0.796078 0.67451 1</ambient>
          </material>
        </visual>
        <collision name='Wall_6_Collision_0'>
          <geometry>
            <box>
              <size>2.32655 0.15 2.5</size>
            </box>
          </geometry>
          <pose frame=''>-1.58672 0 1.25 0 -0 0</pose>
          <max_contacts>10</max_contacts>
          <surface>
            <contact>
              <ode/>
            </contact>
            <bounce/>
            <friction>
              <torsional>
                <ode/>
              </torsional>
              <ode/>
            </friction>
          </surface>
        </collision>
        <visual name='Wall_6_Visual_1'>
          <pose frame=''>1.16328 0 0.25 0 -0 0</pose>
          <geometry>
            <box>
              <size>3.17345 0.15 0.5</size>
            </box>
          </geometry>
          <material>
            <script>
              <uri>file://media/materials/scripts/gazebo.material</uri>
              <name>Gazebo/Grey</name>
            </script>
            <ambient>0.435294 0.796078 0.67451 1</ambient>
          </material>
        </visual>
        <collision name='Wall_6_Collision_1'>
          <geometry>
            <box>
              <size>3.17345 0.15 0.5</size>
            </box>
          </geometry>
          <pose frame=''>1.16328 0 0.25 0 -0 0</pose>
          <max_contacts>10</max_contacts>
          <surface>
            <contact>
              <ode/>
            </contact>
            <bounce/>
            <friction>
              <torsional>
                <ode/>
              </torsional>
              <ode/>
            </friction>
          </surface>
        </collision>
        <visual name='Wall_6_Visual_2'>
          <pose frame=''>1.56328 0 1.5 0 -0 0</pose>
          <geometry>
            <box>
              <size>2.37345 0.15 2</size>
            </box>
          </geometry>
          <material>
            <script>
              <uri>file://media/materials/scripts/gazebo.material</uri>
              <name>Gazebo/Grey</name>
            </script>
            <ambient>0.435294 0.796078 0.67451 1</ambient>
          </material>
        </visual>
        <collision name='Wall_6_Collision_2'>
          <geometry>
            <box>
              <size>2.37345 0.15 2</size>
            </box>
          </geometry>
          <pose frame=''>1.56328 0 1.5 0 -0 0</pose>
          <max_contacts>10</max_contacts>
          <surface>
            <contact>
              <ode/>
            </contact>
            <bounce/>
            <friction>
              <torsional>
                <ode/>
              </torsional>
              <ode/>
            </friction>
          </surface>
        </collision>
        <visual name='Wall_6_Visual_3'>
          <pose frame=''>-0.023447 0 1.9 0 -0 0</pose>
          <geometry>
            <box>
              <size>0.8 0.15 1.2</size>
            </box>
          </geometry>
          <material>
            <script>
              <uri>file://media/materials/scripts/gazebo.material</uri>
              <name>Gazebo/Grey</name>
            </script>
            <ambient>0.435294 0.796078 0.67451 1</ambient>
          </material>
        </visual>
        <collision name='Wall_6_Collision_3'>
          <geometry>
            <box>
              <size>0.8 0.15 1.2</size>
            </box>
          </geometry>
          <pose frame=''>-0.023447 0 1.9 0 -0 0</pose>
          <max_contacts>10</max_contacts>
          <surface>
            <contact>
              <ode/>
            </contact>
            <bounce/>
            <friction>
              <torsional>
                <ode/>
              </torsional>
              <ode/>
            </friction>
          </surface>
        </collision>
        <self_collide>0</self_collide>
        <kinematic>0</kinematic>
        <gravity>1</gravity>
      </link>
      <link name='Wall_7'>
        <collision name='Wall_7_Collision'>
          <geometry>
            <box>
              <size>5 0.15 2.5</size>
            </box>
          </geometry>
          <pose frame=''>0 0 1.25 0 -0 0</pose>
          <max_contacts>10</max_contacts>
          <surface>
            <contact>
              <ode/>
            </contact>
            <bounce/>
            <friction>
              <torsional>
                <ode/>
              </torsional>
              <ode/>
            </friction>
          </surface>
        </collision>
        <visual name='Wall_7_Visual'>
          <pose frame=''>0 0 1.25 0 -0 0</pose>
          <geometry>
            <box>
              <size>5 0.15 2.5</size>
            </box>
          </geometry>
          <material>
            <script>
              <uri>file://media/materials/scripts/gazebo.material</uri>
              <name>Gazebo/Grey</name>
            </script>
            <ambient>0.996078 0.47451 0.0196078 1</ambient>
          </material>
        </visual>
        <pose frame=''>-3.75 2.675 0 0 -0 0</pose>
        <self_collide>0</self_collide>
        <kinematic>0</kinematic>
        <gravity>1</gravity>
      </link>
      <static>1</static>
    </model>
    <model name='Untitled_0'>
      <model name='House 1'>
        <static>1</static>
        <link name='link'>
          <collision name='collision'>
            <geometry>
              <mesh>
                <uri>model://house_1/meshes/house_1.dae</uri>
              </mesh>
            </geometry>
            <max_contacts>10</max_contacts>
            <surface>
              <contact>
                <ode/>
              </contact>
              <bounce/>
              <friction>
                <torsional>
                  <ode/>
                </torsional>
                <ode/>
              </friction>
            </surface>
          </collision>
          <visual name='visual'>
            <geometry>
              <mesh>
                <uri>model://house_1/meshes/house_1.dae</uri>
              </mesh>
            </geometry>
            <material>
              <script>
                <uri>model://house_1/materials/scripts</uri>
                <uri>model://house_1/materials/textures</uri>
                <name>House_1/Diffuse</name>
              </script>
              <shader type='normal_map_object_space'>
                <normal_map>House_1_Normal.png</normal_map>
              </shader>
            </material>
          </visual>
          <self_collide>0</self_collide>
          <kinematic>0</kinematic>
          <gravity>1</gravity>
        </link>
        <pose frame=''>12.0858 -0.49514 0 0 -0 0</pose>
      </model>
      <model name='bookshelf'>
        <static>1</static>
        <link name='link'>
          <inertial>
            <mass>1</mass>
          </inertial>
          <collision name='back'>
            <pose frame=''>0 0.005 0.6 0 -0 0</pose>
            <geometry>
              <box>
                <size>0.9 0.01 1.2</size>
              </box>
            </geometry>
            <max_contacts>10</max_contacts>
            <surface>
              <contact>
                <ode/>
              </contact>
              <bounce/>
              <friction>
                <torsional>
                  <ode/>
                </torsional>
                <ode/>
              </friction>
            </surface>
          </collision>
          <visual name='visual1'>
            <pose frame=''>0 0.005 0.6 0 -0 0</pose>
            <geometry>
              <box>
                <size>0.9 0.01 1.2</size>
              </box>
            </geometry>
            <material>
              <script>
                <uri>file://media/materials/scripts/gazebo.material</uri>
                <name>Gazebo/Wood</name>
              </script>
            </material>
          </visual>
          <collision name='left_side'>
            <pose frame=''>0.45 -0.195 0.6 0 -0 0</pose>
            <geometry>
              <box>
                <size>0.02 0.4 1.2</size>
              </box>
            </geometry>
            <max_contacts>10</max_contacts>
            <surface>
              <contact>
                <ode/>
              </contact>
              <bounce/>
              <friction>
                <torsional>
                  <ode/>
                </torsional>
                <ode/>
              </friction>
            </surface>
          </collision>
          <visual name='visual2'>
            <pose frame=''>0.45 -0.195 0.6 0 -0 0</pose>
            <geometry>
              <box>
                <size>0.02 0.4 1.2</size>
              </box>
            </geometry>
            <material>
              <script>
                <uri>file://media/materials/scripts/gazebo.material</uri>
                <name>Gazebo/Wood</name>
              </script>
            </material>
          </visual>
          <collision name='right_side'>
            <pose frame=''>-0.45 -0.195 0.6 0 -0 0</pose>
            <geometry>
              <box>
                <size>0.02 0.4 1.2</size>
              </box>
            </geometry>
            <max_contacts>10</max_contacts>
            <surface>
              <contact>
                <ode/>
              </contact>
              <bounce/>
              <friction>
                <torsional>
                  <ode/>
                </torsional>
                <ode/>
              </friction>
            </surface>
          </collision>
          <visual name='visual3'>
            <pose frame=''>-0.45 -0.195 0.6 0 -0 0</pose>
            <geometry>
              <box>
                <size>0.02 0.4 1.2</size>
              </box>
            </geometry>
            <material>
              <script>
                <uri>file://media/materials/scripts/gazebo.material</uri>
                <name>Gazebo/Wood</name>
              </script>
            </material>
          </visual>
          <collision name='bottom'>
            <pose frame=''>0 -0.195 0.03 0 -0 0</pose>
            <geometry>
              <box>
                <size>0.88 0.4 0.06</size>
              </box>
            </geometry>
            <max_contacts>10</max_contacts>
            <surface>
              <contact>
                <ode/>
              </contact>
              <bounce/>
              <friction>
                <torsional>
                  <ode/>
                </torsional>
                <ode/>
              </friction>
            </surface>
          </collision>
          <visual name='visual4'>
            <pose frame=''>0 -0.195 0.03 0 -0 0</pose>
            <geometry>
              <box>
                <size>0.88 0.4 0.06</size>
              </box>
            </geometry>
            <material>
              <script>
                <uri>file://media/materials/scripts/gazebo.material</uri>
                <name>Gazebo/Wood</name>
              </script>
            </material>
          </visual>
          <collision name='top'>
            <pose frame=''>0 -0.195 1.19 0 -0 0</pose>
            <geometry>
              <box>
                <size>0.88 0.4 0.02</size>
              </box>
            </geometry>
            <max_contacts>10</max_contacts>
            <surface>
              <contact>
                <ode/>
              </contact>
              <bounce/>
              <friction>
                <torsional>
                  <ode/>
                </torsional>
                <ode/>
              </friction>
            </surface>
          </collision>
          <visual name='visual5'>
            <pose frame=''>0 -0.195 1.19 0 -0 0</pose>
            <geometry>
              <box>
                <size>0.88 0.4 0.02</size>
              </box>
            </geometry>
            <material>
              <script>
                <uri>file://media/materials/scripts/gazebo.material</uri>
                <name>Gazebo/Wood</name>
              </script>
            </material>
          </visual>
          <collision name='low_shelf'>
            <pose frame=''>0 -0.195 0.43 0 -0 0</pose>
            <geometry>
              <box>
                <size>0.88 0.4 0.02</size>
              </box>
            </geometry>
            <max_contacts>10</max_contacts>
            <surface>
              <contact>
                <ode/>
              </contact>
              <bounce/>
              <friction>
                <torsional>
                  <ode/>
                </torsional>
                <ode/>
              </friction>
            </surface>
          </collision>
          <visual name='visual6'>
            <pose frame=''>0 -0.195 0.43 0 -0 0</pose>
            <geometry>
              <box>
                <size>0.88 0.4 0.02</size>
              </box>
            </geometry>
            <material>
              <script>
                <uri>file://media/materials/scripts/gazebo.material</uri>
                <name>Gazebo/Wood</name>
              </script>
            </material>
          </visual>
          <collision name='high_shelf'>
            <pose frame=''>0 -0.195 0.8 0 -0 0</pose>
            <geometry>
              <box>
                <size>0.88 0.4 0.02</size>
              </box>
            </geometry>
            <max_contacts>10</max_contacts>
            <surface>
              <contact>
                <ode/>
              </contact>
              <bounce/>
              <friction>
                <torsional>
                  <ode/>
                </torsional>
                <ode/>
              </friction>
            </surface>
          </collision>
          <visual name='visual7'>
            <pose frame=''>0 -0.195 0.8 0 -0 0</pose>
            <geometry>
              <box>
                <size>0.88 0.4 0.02</size>
              </box>
            </geometry>
            <material>
              <script>
                <uri>file://media/materials/scripts/gazebo.material</uri>
                <name>Gazebo/Wood</name>
              </script>
            </material>
          </visual>
          <self_collide>0</self_collide>
          <kinematic>0</kinematic>
          <gravity>1</gravity>
        </link>
        <pose frame=''>-5.90595 4.03821 0 0 -0 0</pose>
      </model>
      <model name='cafe_table'>
        <static>1</static>
        <link name='link'>
          <collision name='surface'>
            <pose frame=''>0 0 0.755 0 -0 0</pose>
            <geometry>
              <box>
                <size>0.913 0.913 0.04</size>
              </box>
            </geometry>
            <max_contacts>10</max_contacts>
            <surface>
              <contact>
                <ode/>
              </contact>
              <bounce/>
              <friction>
                <torsional>
                  <ode/>
                </torsional>
                <ode/>
              </friction>
            </surface>
          </collision>
          <collision name='column'>
            <pose frame=''>0 0 0.37 0 -0 0</pose>
            <geometry>
              <box>
                <size>0.042 0.042 0.74</size>
              </box>
            </geometry>
            <max_contacts>10</max_contacts>
            <surface>
              <contact>
                <ode/>
              </contact>
              <bounce/>
              <friction>
                <torsional>
                  <ode/>
                </torsional>
                <ode/>
              </friction>
            </surface>
          </collision>
          <collision name='base'>
            <pose frame=''>0 0 0.02 0 -0 0</pose>
            <geometry>
              <box>
                <size>0.56 0.56 0.04</size>
              </box>
            </geometry>
            <max_contacts>10</max_contacts>
            <surface>
              <contact>
                <ode/>
              </contact>
              <bounce/>
              <friction>
                <torsional>
                  <ode/>
                </torsional>
                <ode/>
              </friction>
            </surface>
          </collision>
          <visual name='visual'>
            <geometry>
              <mesh>
                <uri>model://cafe_table/meshes/cafe_table.dae</uri>
              </mesh>
            </geometry>
          </visual>
          <self_collide>0</self_collide>
          <kinematic>0</kinematic>
          <gravity>1</gravity>
        </link>
        <pose frame=''>-2.32229 2.50486 0 0 -0 0</pose>
      </model>
      <model name='cart_front_steer'>
        <link name='chassis'>
          <pose frame=''>0 0 0.15 0 -0 0</pose>
          <inertial>
            <pose frame=''>0.1 0 0 0 -0 0</pose>
            <mass>10</mass>
            <inertia>
              <ixx>0.216667</ixx>
              <iyy>0.841667</iyy>
              <izz>1.04167</izz>
              <ixy>0</ixy>
              <ixz>0</ixz>
              <iyz>0</iyz>
            </inertia>
          </inertial>
          <collision name='collision'>
            <geometry>
              <box>
                <size>1 0.5 0.1</size>
              </box>
            </geometry>
            <max_contacts>10</max_contacts>
            <surface>
              <contact>
                <ode/>
              </contact>
              <bounce/>
              <friction>
                <torsional>
                  <ode/>
                </torsional>
                <ode/>
              </friction>
            </surface>
          </collision>
          <visual name='visual'>
            <geometry>
              <box>
                <size>1 0.5 0.1</size>
              </box>
            </geometry>
            <material>
              <script>
                <uri>file://media/materials/scripts/gazebo.material</uri>
                <name>Gazebo/Grey</name>
              </script>
            </material>
          </visual>
          <self_collide>0</self_collide>
          <kinematic>0</kinematic>
          <gravity>1</gravity>
        </link>
        <link name='wheel_front_left'>
          <pose frame=''>0.5 0.298 0.15 -1.5708 -0.087266 0</pose>
          <inertial>
            <mass>0.5</mass>
            <inertia>
              <ixx>0.00307917</ixx>
              <iyy>0.00307917</iyy>
              <izz>0.005625</izz>
              <ixy>0</ixy>
              <ixz>0</ixz>
              <iyz>0</iyz>
            </inertia>
          </inertial>
          <collision name='collision'>
            <geometry>
              <cylinder>
                <radius>0.15</radius>
                <length>0.08</length>
              </cylinder>
            </geometry>
            <max_contacts>10</max_contacts>
            <surface>
              <contact>
                <ode/>
              </contact>
              <bounce/>
              <friction>
                <torsional>
                  <ode/>
                </torsional>
                <ode/>
              </friction>
            </surface>
          </collision>
          <visual name='visual'>
            <geometry>
              <cylinder>
                <radius>0.15</radius>
                <length>0.08</length>
              </cylinder>
            </geometry>
            <material>
              <script>
                <uri>file://media/materials/scripts/gazebo.material</uri>
                <name>Gazebo/Black</name>
              </script>
            </material>
          </visual>
          <self_collide>0</self_collide>
          <kinematic>0</kinematic>
          <gravity>1</gravity>
        </link>
        <joint name='wheel_front_left_steer_spin' type='universal'>
          <parent>chassis</parent>
          <child>wheel_front_left</child>
          <axis>
            <xyz>0 -1 0</xyz>
            <limit>
              <lower>-0.610865</lower>
              <upper>0.610865</upper>
            </limit>
            <use_parent_model_frame>0</use_parent_model_frame>
            <dynamics>
              <spring_reference>0</spring_reference>
              <spring_stiffness>0</spring_stiffness>
            </dynamics>
          </axis>
          <axis2>
            <xyz>0 0 1</xyz>
            <use_parent_model_frame>0</use_parent_model_frame>
            <dynamics>
              <spring_reference>0</spring_reference>
              <spring_stiffness>0</spring_stiffness>
            </dynamics>
          </axis2>
        </joint>
        <link name='wheel_front_right'>
          <pose frame=''>0.5 -0.298 0.15 -1.5708 -0.087266 0</pose>
          <inertial>
            <mass>0.5</mass>
            <inertia>
              <ixx>0.00307917</ixx>
              <iyy>0.00307917</iyy>
              <izz>0.005625</izz>
              <ixy>0</ixy>
              <ixz>0</ixz>
              <iyz>0</iyz>
            </inertia>
          </inertial>
          <collision name='collision'>
            <geometry>
              <cylinder>
                <radius>0.15</radius>
                <length>0.08</length>
              </cylinder>
            </geometry>
            <max_contacts>10</max_contacts>
            <surface>
              <contact>
                <ode/>
              </contact>
              <bounce/>
              <friction>
                <torsional>
                  <ode/>
                </torsional>
                <ode/>
              </friction>
            </surface>
          </collision>
          <visual name='visual'>
            <geometry>
              <cylinder>
                <radius>0.15</radius>
                <length>0.08</length>
              </cylinder>
            </geometry>
            <material>
              <script>
                <uri>file://media/materials/scripts/gazebo.material</uri>
                <name>Gazebo/Black</name>
              </script>
            </material>
          </visual>
          <self_collide>0</self_collide>
          <kinematic>0</kinematic>
          <gravity>1</gravity>
        </link>
        <joint name='wheel_front_right_steer_spin' type='universal'>
          <parent>chassis</parent>
          <child>wheel_front_right</child>
          <axis>
            <xyz>0 -1 0</xyz>
            <limit>
              <lower>-0.610865</lower>
              <upper>0.610865</upper>
            </limit>
            <use_parent_model_frame>0</use_parent_model_frame>
            <dynamics>
              <spring_reference>0</spring_reference>
              <spring_stiffness>0</spring_stiffness>
            </dynamics>
          </axis>
          <axis2>
            <xyz>0 0 1</xyz>
            <use_parent_model_frame>0</use_parent_model_frame>
            <dynamics>
              <spring_reference>0</spring_reference>
              <spring_stiffness>0</spring_stiffness>
            </dynamics>
          </axis2>
        </joint>
        <link name='wheel_rear_left'>
          <pose frame=''>-0.5 0.298 0.15 -1.5708 0 0</pose>
          <inertial>
            <mass>0.5</mass>
            <inertia>
              <ixx>0.00307917</ixx>
              <iyy>0.00307917</iyy>
              <izz>0.005625</izz>
              <ixy>0</ixy>
              <ixz>0</ixz>
              <iyz>0</iyz>
            </inertia>
          </inertial>
          <collision name='collision'>
            <geometry>
              <cylinder>
                <radius>0.15</radius>
                <length>0.08</length>
              </cylinder>
            </geometry>
            <max_contacts>10</max_contacts>
            <surface>
              <contact>
                <ode/>
              </contact>
              <bounce/>
              <friction>
                <torsional>
                  <ode/>
                </torsional>
                <ode/>
              </friction>
            </surface>
          </collision>
          <visual name='visual'>
            <geometry>
              <cylinder>
                <radius>0.15</radius>
                <length>0.08</length>
              </cylinder>
            </geometry>
            <material>
              <script>
                <uri>file://media/materials/scripts/gazebo.material</uri>
                <name>Gazebo/Black</name>
              </script>
            </material>
          </visual>
          <self_collide>0</self_collide>
          <kinematic>0</kinematic>
          <gravity>1</gravity>
        </link>
        <joint name='wheel_rear_left_spin' type='revolute'>
          <parent>chassis</parent>
          <child>wheel_rear_left</child>
          <axis>
            <xyz>0 0 1</xyz>
            <use_parent_model_frame>0</use_parent_model_frame>
            <limit>
              <lower>-1e+16</lower>
              <upper>1e+16</upper>
            </limit>
            <dynamics>
              <spring_reference>0</spring_reference>
              <spring_stiffness>0</spring_stiffness>
            </dynamics>
          </axis>
        </joint>
        <link name='wheel_rear_right'>
          <pose frame=''>-0.5 -0.298 0.15 -1.5708 0 0</pose>
          <inertial>
            <mass>0.5</mass>
            <inertia>
              <ixx>0.00307917</ixx>
              <iyy>0.00307917</iyy>
              <izz>0.005625</izz>
              <ixy>0</ixy>
              <ixz>0</ixz>
              <iyz>0</iyz>
            </inertia>
          </inertial>
          <collision name='collision'>
            <geometry>
              <cylinder>
                <radius>0.15</radius>
                <length>0.08</length>
              </cylinder>
            </geometry>
            <max_contacts>10</max_contacts>
            <surface>
              <contact>
                <ode/>
              </contact>
              <bounce/>
              <friction>
                <torsional>
                  <ode/>
                </torsional>
                <ode/>
              </friction>
            </surface>
          </collision>
          <visual name='visual'>
            <geometry>
              <cylinder>
                <radius>0.15</radius>
                <length>0.08</length>
              </cylinder>
            </geometry>
            <material>
              <script>
                <uri>file://media/materials/scripts/gazebo.material</uri>
                <name>Gazebo/Black</name>
              </script>
            </material>
          </visual>
          <self_collide>0</self_collide>
          <kinematic>0</kinematic>
          <gravity>1</gravity>
        </link>
        <joint name='wheel_rear_right_spin' type='revolute'>
          <parent>chassis</parent>
          <child>wheel_rear_right</child>
          <axis>
            <xyz>0 0 1</xyz>
            <use_parent_model_frame>0</use_parent_model_frame>
            <limit>
              <lower>-1e+16</lower>
              <upper>1e+16</upper>
            </limit>
            <dynamics>
              <spring_reference>0</spring_reference>
              <spring_stiffness>0</spring_stiffness>
            </dynamics>
          </axis>
        </joint>
        <pose frame=''>-5.32229 -6.09284 0 0 -0 0</pose>
      </model>
      <model name='cart_rigid_suspension'>
        <link name='chassis'>
          <pose frame=''>0 0 0.15 0 -0 0</pose>
          <inertial>
            <pose frame=''>0.1 0 0 0 -0 0</pose>
            <mass>10</mass>
            <inertia>
              <ixx>0.216667</ixx>
              <iyy>0.841667</iyy>
              <izz>1.04167</izz>
              <ixy>0</ixy>
              <ixz>0</ixz>
              <iyz>0</iyz>
            </inertia>
          </inertial>
          <collision name='collision'>
            <geometry>
              <box>
                <size>1 0.5 0.1</size>
              </box>
            </geometry>
            <max_contacts>10</max_contacts>
            <surface>
              <contact>
                <ode/>
              </contact>
              <bounce/>
              <friction>
                <torsional>
                  <ode/>
                </torsional>
                <ode/>
              </friction>
            </surface>
          </collision>
          <visual name='visual'>
            <geometry>
              <box>
                <size>1 0.5 0.1</size>
              </box>
            </geometry>
            <material>
              <script>
                <uri>file://media/materials/scripts/gazebo.material</uri>
                <name>Gazebo/Grey</name>
              </script>
            </material>
          </visual>
          <self_collide>0</self_collide>
          <kinematic>0</kinematic>
          <gravity>1</gravity>
        </link>
        <link name='wheel_front_left'>
          <pose frame=''>0.5 0.298 0.15 -1.5708 0 0</pose>
          <inertial>
            <mass>0.5</mass>
            <inertia>
              <ixx>0.00307917</ixx>
              <iyy>0.00307917</iyy>
              <izz>0.005625</izz>
              <ixy>0</ixy>
              <ixz>0</ixz>
              <iyz>0</iyz>
            </inertia>
          </inertial>
          <collision name='collision'>
            <geometry>
              <cylinder>
                <radius>0.15</radius>
                <length>0.08</length>
              </cylinder>
            </geometry>
            <max_contacts>10</max_contacts>
            <surface>
              <contact>
                <ode/>
              </contact>
              <bounce/>
              <friction>
                <torsional>
                  <ode/>
                </torsional>
                <ode/>
              </friction>
            </surface>
          </collision>
          <visual name='visual'>
            <geometry>
              <cylinder>
                <radius>0.15</radius>
                <length>0.08</length>
              </cylinder>
            </geometry>
            <material>
              <script>
                <uri>file://media/materials/scripts/gazebo.material</uri>
                <name>Gazebo/Black</name>
              </script>
            </material>
          </visual>
          <self_collide>0</self_collide>
          <kinematic>0</kinematic>
          <gravity>1</gravity>
        </link>
        <joint name='wheel_front_left_spin' type='revolute'>
          <parent>chassis</parent>
          <child>wheel_front_left</child>
          <axis>
            <xyz>0 0 1</xyz>
            <use_parent_model_frame>0</use_parent_model_frame>
            <limit>
              <lower>-1e+16</lower>
              <upper>1e+16</upper>
            </limit>
            <dynamics>
              <spring_reference>0</spring_reference>
              <spring_stiffness>0</spring_stiffness>
            </dynamics>
          </axis>
        </joint>
        <link name='wheel_front_right'>
          <pose frame=''>0.5 -0.298 0.15 -1.5708 0 0</pose>
          <inertial>
            <mass>0.5</mass>
            <inertia>
              <ixx>0.00307917</ixx>
              <iyy>0.00307917</iyy>
              <izz>0.005625</izz>
              <ixy>0</ixy>
              <ixz>0</ixz>
              <iyz>0</iyz>
            </inertia>
          </inertial>
          <collision name='collision'>
            <geometry>
              <cylinder>
                <radius>0.15</radius>
                <length>0.08</length>
              </cylinder>
            </geometry>
            <max_contacts>10</max_contacts>
            <surface>
              <contact>
                <ode/>
              </contact>
              <bounce/>
              <friction>
                <torsional>
                  <ode/>
                </torsional>
                <ode/>
              </friction>
            </surface>
          </collision>
          <visual name='visual'>
            <geometry>
              <cylinder>
                <radius>0.15</radius>
                <length>0.08</length>
              </cylinder>
            </geometry>
            <material>
              <script>
                <uri>file://media/materials/scripts/gazebo.material</uri>
                <name>Gazebo/Black</name>
              </script>
            </material>
          </visual>
          <self_collide>0</self_collide>
          <kinematic>0</kinematic>
          <gravity>1</gravity>
        </link>
        <joint name='wheel_front_right_spin' type='revolute'>
          <parent>chassis</parent>
          <child>wheel_front_right</child>
          <axis>
            <xyz>0 0 1</xyz>
            <use_parent_model_frame>0</use_parent_model_frame>
            <limit>
              <lower>-1e+16</lower>
              <upper>1e+16</upper>
            </limit>
            <dynamics>
              <spring_reference>0</spring_reference>
              <spring_stiffness>0</spring_stiffness>
            </dynamics>
          </axis>
        </joint>
        <link name='wheel_rear_left'>
          <pose frame=''>-0.5 0.298 0.15 -1.5708 0 0</pose>
          <inertial>
            <mass>0.5</mass>
            <inertia>
              <ixx>0.00307917</ixx>
              <iyy>0.00307917</iyy>
              <izz>0.005625</izz>
              <ixy>0</ixy>
              <ixz>0</ixz>
              <iyz>0</iyz>
            </inertia>
          </inertial>
          <collision name='collision'>
            <geometry>
              <cylinder>
                <radius>0.15</radius>
                <length>0.08</length>
              </cylinder>
            </geometry>
            <max_contacts>10</max_contacts>
            <surface>
              <contact>
                <ode/>
              </contact>
              <bounce/>
              <friction>
                <torsional>
                  <ode/>
                </torsional>
                <ode/>
              </friction>
            </surface>
          </collision>
          <visual name='visual'>
            <geometry>
              <cylinder>
                <radius>0.15</radius>
                <length>0.08</length>
              </cylinder>
            </geometry>
            <material>
              <script>
                <uri>file://media/materials/scripts/gazebo.material</uri>
                <name>Gazebo/Black</name>
              </script>
            </material>
          </visual>
          <self_collide>0</self_collide>
          <kinematic>0</kinematic>
          <gravity>1</gravity>
        </link>
        <joint name='wheel_rear_left_spin' type='revolute'>
          <parent>chassis</parent>
          <child>wheel_rear_left</child>
          <axis>
            <xyz>0 0 1</xyz>
            <use_parent_model_frame>0</use_parent_model_frame>
            <limit>
              <lower>-1e+16</lower>
              <upper>1e+16</upper>
            </limit>
            <dynamics>
              <spring_reference>0</spring_reference>
              <spring_stiffness>0</spring_stiffness>
            </dynamics>
          </axis>
        </joint>
        <link name='wheel_rear_right'>
          <pose frame=''>-0.5 -0.298 0.15 -1.5708 0 0</pose>
          <inertial>
            <mass>0.5</mass>
            <inertia>
              <ixx>0.00307917</ixx>
              <iyy>0.00307917</iyy>
              <izz>0.005625</izz>
              <ixy>0</ixy>
              <ixz>0</ixz>
              <iyz>0</iyz>
            </inertia>
          </inertial>
          <collision name='collision'>
            <geometry>
              <cylinder>
                <radius>0.15</radius>
                <length>0.08</length>
              </cylinder>
            </geometry>
            <max_contacts>10</max_contacts>
            <surface>
              <contact>
                <ode/>
              </contact>
              <bounce/>
              <friction>
                <torsional>
                  <ode/>
                </torsional>
                <ode/>
              </friction>
            </surface>
          </collision>
          <visual name='visual'>
            <geometry>
              <cylinder>
                <radius>0.15</radius>
                <length>0.08</length>
              </cylinder>
            </geometry>
            <material>
              <script>
                <uri>file://media/materials/scripts/gazebo.material</uri>
                <name>Gazebo/Black</name>
              </script>
            </material>
          </visual>
          <self_collide>0</self_collide>
          <kinematic>0</kinematic>
          <gravity>1</gravity>
        </link>
        <joint name='wheel_rear_right_spin' type='revolute'>
          <parent>chassis</parent>
          <child>wheel_rear_right</child>
          <axis>
            <xyz>0 0 1</xyz>
            <use_parent_model_frame>0</use_parent_model_frame>
            <limit>
              <lower>-1e+16</lower>
              <upper>1e+16</upper>
            </limit>
            <dynamics>
              <spring_reference>0</spring_reference>
              <spring_stiffness>0</spring_stiffness>
            </dynamics>
          </axis>
        </joint>
        <pose frame=''>-3.32229 -5.96481 0 0 -0 0</pose>
      </model>
      <model name='turtlebot'>
        <link name='rack'>
          <inertial>
            <pose frame=''>0.001453 -0.000453 0.029787 0 -0 0</pose>
            <inertia>
              <ixx>0.05864</ixx>
              <ixy>0.000124</ixy>
              <ixz>0.000615</ixz>
              <iyy>0.058786</iyy>
              <iyz>1.4e-05</iyz>
              <izz>1.53244</izz>
            </inertia>
            <mass>2.234</mass>
          </inertial>
          <collision name='plate_0_collision'>
            <pose frame=''>-0.04334 0 0.084757 0 -0 0</pose>
            <geometry>
              <box>
                <size>0.233502 0.314845 0.006401</size>
              </box>
            </geometry>
            <max_contacts>10</max_contacts>
            <surface>
              <contact>
                <ode/>
              </contact>
              <bounce/>
              <friction>
                <torsional>
                  <ode/>
                </torsional>
                <ode/>
              </friction>
            </surface>
          </collision>
          <visual name='plate_0_visual'>
            <pose frame=''>-0.04334 0 0.084757 0 -0 0</pose>
            <geometry>
              <mesh>
                <uri>model://turtlebot/meshes/plate_0_logo.dae</uri>
              </mesh>
            </geometry>
          </visual>
          <collision name='plate_1_collision'>
            <pose frame=''>-0.00266 0 0.141907 0 -0 0</pose>
            <geometry>
              <box>
                <size>0.314856 0.314856 0.006401</size>
              </box>
            </geometry>
            <max_contacts>10</max_contacts>
            <surface>
              <contact>
                <ode/>
              </contact>
              <bounce/>
              <friction>
                <torsional>
                  <ode/>
                </torsional>
                <ode/>
              </friction>
            </surface>
          </collision>
          <visual name='plate_1_visual'>
            <pose frame=''>-0.00266 0 0.141907 0 -0 0</pose>
            <geometry>
              <mesh>
                <uri>model://turtlebot/meshes/plate_1_logo.dae</uri>
              </mesh>
            </geometry>
          </visual>
          <collision name='plate_2_collision'>
            <pose frame=''>-0.00266 0 0.199108 0 -0 0</pose>
            <geometry>
              <box>
                <size>0.314856 0.314856 0.006401</size>
              </box>
            </geometry>
            <max_contacts>10</max_contacts>
            <surface>
              <contact>
                <ode/>
              </contact>
              <bounce/>
              <friction>
                <torsional>
                  <ode/>
                </torsional>
                <ode/>
              </friction>
            </surface>
          </collision>
          <visual name='plate_2_visual'>
            <pose frame=''>-0.00266 0 0.199108 0 -0 0</pose>
            <geometry>
              <mesh>
                <uri>model://turtlebot/meshes/plate_1_logo.dae</uri>
              </mesh>
            </geometry>
          </visual>
          <collision name='plate_3_collision'>
            <pose frame=''>-0.01582 0 0.405457 0 -0 0</pose>
            <geometry>
              <box>
                <size>0.288 0.315 0.006401</size>
              </box>
            </geometry>
            <max_contacts>10</max_contacts>
            <surface>
              <contact>
                <ode/>
              </contact>
              <bounce/>
              <friction>
                <torsional>
                  <ode/>
                </torsional>
                <ode/>
              </friction>
            </surface>
          </collision>
          <visual name='plate_3_visual'>
            <pose frame=''>-0.01582 0 0.405457 0 -0 0</pose>
            <geometry>
              <mesh>
                <uri>model://turtlebot/meshes/plate_2_logo.dae</uri>
              </mesh>
            </geometry>
          </visual>
          <collision name='spacer_0_collision'>
            <pose frame=''>-0.00254 0.111468 0.079992 0 -0 0</pose>
            <geometry>
              <cylinder>
                <radius>0.0127</radius>
                <length>0.003175</length>
              </cylinder>
            </geometry>
            <max_contacts>10</max_contacts>
            <surface>
              <contact>
                <ode/>
              </contact>
              <bounce/>
              <friction>
                <torsional>
                  <ode/>
                </torsional>
                <ode/>
              </friction>
            </surface>
          </collision>
          <visual name='spacer_0_visual'>
            <pose frame=''>-0.00254 0.111468 0.079992 0 -0 0</pose>
            <geometry>
              <mesh>
                <uri>model://turtlebot/meshes/68-02403-125_Spacer.dae</uri>
              </mesh>
            </geometry>
          </visual>
          <collision name='spacer_1_collision'>
            <pose frame=''>-0.00254 -0.111468 0.079992 0 -0 0</pose>
            <geometry>
              <cylinder>
                <radius>0.0127</radius>
                <length>0.003175</length>
              </cylinder>
            </geometry>
            <max_contacts>10</max_contacts>
            <surface>
              <contact>
                <ode/>
              </contact>
              <bounce/>
              <friction>
                <torsional>
                  <ode/>
                </torsional>
                <ode/>
              </friction>
            </surface>
          </collision>
          <visual name='spacer_1_visual'>
            <pose frame=''>-0.00254 -0.111468 0.079992 0 -0 0</pose>
            <geometry>
              <mesh>
                <uri>model://turtlebot/meshes/68-02403-125_Spacer.dae</uri>
              </mesh>
            </geometry>
          </visual>
          <collision name='spacer_2_collision'>
            <pose frame=''>-0.07239 -0.111468 0.079992 0 -0 0</pose>
            <geometry>
              <cylinder>
                <radius>0.0127</radius>
                <length>0.003175</length>
              </cylinder>
            </geometry>
            <max_contacts>10</max_contacts>
            <surface>
              <contact>
                <ode/>
              </contact>
              <bounce/>
              <friction>
                <torsional>
                  <ode/>
                </torsional>
                <ode/>
              </friction>
            </surface>
          </collision>
          <visual name='spacer_2_visual'>
            <pose frame=''>-0.07239 -0.111468 0.079992 0 -0 0</pose>
            <geometry>
              <mesh>
                <uri>model://turtlebot/meshes/68-02403-125_Spacer.dae</uri>
              </mesh>
            </geometry>
          </visual>
          <collision name='spacer_3_collision'>
            <pose frame=''>-0.07239 0.111468 0.079992 0 -0 0</pose>
            <geometry>
              <cylinder>
                <radius>0.0127</radius>
                <length>0.003175</length>
              </cylinder>
            </geometry>
            <max_contacts>10</max_contacts>
            <surface>
              <contact>
                <ode/>
              </contact>
              <bounce/>
              <friction>
                <torsional>
                  <ode/>
                </torsional>
                <ode/>
              </friction>
            </surface>
          </collision>
          <visual name='spacer_3_visual'>
            <pose frame=''>-0.07239 0.111468 0.079992 0 -0 0</pose>
            <geometry>
              <mesh>
                <uri>model://turtlebot/meshes/68-02403-125_Spacer.dae</uri>
              </mesh>
            </geometry>
          </visual>
          <collision name='standoff_2in_0_collision'>
            <pose frame=''>0.06764 0.13142 0.08798 0 -0 0</pose>
            <geometry>
              <cylinder>
                <radius>0.0381</radius>
                <length>0.0635</length>
              </cylinder>
            </geometry>
            <max_contacts>10</max_contacts>
            <surface>
              <contact>
                <ode/>
              </contact>
              <bounce/>
              <friction>
                <torsional>
                  <ode/>
                </torsional>
                <ode/>
              </friction>
            </surface>
          </collision>
          <visual name='standoff_2in_0_visual'>
            <pose frame=''>0.06764 0.13142 0.08798 0 -0 0</pose>
            <geometry>
              <mesh>
                <uri>model://turtlebot/meshes/68-04552-2000-RA_Turtlebot_M-F_Standoff.dae</uri>
              </mesh>
            </geometry>
          </visual>
          <collision name='standoff_2in_1_collision'>
            <pose frame=''>0.06764 -0.13142 0.08798 0 -0 0</pose>
            <geometry>
              <cylinder>
                <radius>0.0381</radius>
                <length>0.0635</length>
              </cylinder>
            </geometry>
            <max_contacts>10</max_contacts>
            <surface>
              <contact>
                <ode/>
              </contact>
              <bounce/>
              <friction>
                <torsional>
                  <ode/>
                </torsional>
                <ode/>
              </friction>
            </surface>
          </collision>
          <visual name='standoff_2in_1_visual'>
            <pose frame=''>0.06764 -0.13142 0.08798 0 -0 0</pose>
            <geometry>
              <mesh>
                <uri>model://turtlebot/meshes/68-04552-2000-RA_Turtlebot_M-F_Standoff.dae</uri>
              </mesh>
            </geometry>
          </visual>
          <collision name='standoff_2in_2_collision'>
            <pose frame=''>-0.052832 -0.13142 0.08798 0 -0 0</pose>
            <geometry>
              <cylinder>
                <radius>0.0381</radius>
                <length>0.0635</length>
              </cylinder>
            </geometry>
            <max_contacts>10</max_contacts>
            <surface>
              <contact>
                <ode/>
              </contact>
              <bounce/>
              <friction>
                <torsional>
                  <ode/>
                </torsional>
                <ode/>
              </friction>
            </surface>
          </collision>
          <visual name='standoff_2in_2_visual'>
            <pose frame=''>-0.052832 -0.13142 0.08798 0 -0 0</pose>
            <geometry>
              <mesh>
                <uri>model://turtlebot/meshes/68-04552-2000-RA_Turtlebot_M-F_Standoff.dae</uri>
              </mesh>
            </geometry>
          </visual>
          <collision name='standoff_2in_3_collision'>
            <pose frame=''>-0.052832 0.13142 0.08798 0 -0 0</pose>
            <geometry>
              <cylinder>
                <radius>0.0381</radius>
                <length>0.0635</length>
              </cylinder>
            </geometry>
            <max_contacts>10</max_contacts>
            <surface>
              <contact>
                <ode/>
              </contact>
              <bounce/>
              <friction>
                <torsional>
                  <ode/>
                </torsional>
                <ode/>
              </friction>
            </surface>
          </collision>
          <visual name='standoff_2in_3_visual'>
            <pose frame=''>-0.052832 0.13142 0.08798 0 -0 0</pose>
            <geometry>
              <mesh>
                <uri>model://turtlebot/meshes/68-04552-2000-RA_Turtlebot_M-F_Standoff.dae</uri>
              </mesh>
            </geometry>
          </visual>
          <collision name='standoff_2in_4_collision'>
            <pose frame=''>0.06764 0.13142 0.14513 0 -0 0</pose>
            <geometry>
              <cylinder>
                <radius>0.0381</radius>
                <length>0.0635</length>
              </cylinder>
            </geometry>
            <max_contacts>10</max_contacts>
            <surface>
              <contact>
                <ode/>
              </contact>
              <bounce/>
              <friction>
                <torsional>
                  <ode/>
                </torsional>
                <ode/>
              </friction>
            </surface>
          </collision>
          <visual name='standoff_2in_4_visual'>
            <pose frame=''>0.06764 0.13142 0.14513 0 -0 0</pose>
            <geometry>
              <mesh>
                <uri>model://turtlebot/meshes/68-04552-2000-RA_Turtlebot_M-F_Standoff.dae</uri>
              </mesh>
            </geometry>
          </visual>
          <collision name='standoff_2in_5_collision'>
            <pose frame=''>0.06764 -0.13142 0.14513 0 -0 0</pose>
            <geometry>
              <cylinder>
                <radius>0.0381</radius>
                <length>0.0635</length>
              </cylinder>
            </geometry>
            <max_contacts>10</max_contacts>
            <surface>
              <contact>
                <ode/>
              </contact>
              <bounce/>
              <friction>
                <torsional>
                  <ode/>
                </torsional>
                <ode/>
              </friction>
            </surface>
          </collision>
          <visual name='standoff_2in_5_visual'>
            <pose frame=''>0.06764 -0.13142 0.14513 0 -0 0</pose>
            <geometry>
              <mesh>
                <uri>model://turtlebot/meshes/68-04552-2000-RA_Turtlebot_M-F_Standoff.dae</uri>
              </mesh>
            </geometry>
          </visual>
          <collision name='standoff_2in_6_collision'>
            <pose frame=''>-0.052832 -0.13142 0.14513 0 -0 0</pose>
            <geometry>
              <cylinder>
                <radius>0.0381</radius>
                <length>0.0635</length>
              </cylinder>
            </geometry>
            <max_contacts>10</max_contacts>
            <surface>
              <contact>
                <ode/>
              </contact>
              <bounce/>
              <friction>
                <torsional>
                  <ode/>
                </torsional>
                <ode/>
              </friction>
            </surface>
          </collision>
          <visual name='standoff_2in_6_visual'>
            <pose frame=''>-0.052832 -0.13142 0.14513 0 -0 0</pose>
            <geometry>
              <mesh>
                <uri>model://turtlebot/meshes/68-04552-2000-RA_Turtlebot_M-F_Standoff.dae</uri>
              </mesh>
            </geometry>
          </visual>
          <collision name='standoff_2in_7_collision'>
            <pose frame=''>-0.052832 0.13142 0.14513 0 -0 0</pose>
            <geometry>
              <cylinder>
                <radius>0.0381</radius>
                <length>0.0635</length>
              </cylinder>
            </geometry>
            <max_contacts>10</max_contacts>
            <surface>
              <contact>
                <ode/>
              </contact>
              <bounce/>
              <friction>
                <torsional>
                  <ode/>
                </torsional>
                <ode/>
              </friction>
            </surface>
          </collision>
          <visual name='standoff_2in_7_visual'>
            <pose frame=''>-0.052832 0.13142 0.14513 0 -0 0</pose>
            <geometry>
              <mesh>
                <uri>model://turtlebot/meshes/68-04552-2000-RA_Turtlebot_M-F_Standoff.dae</uri>
              </mesh>
            </geometry>
          </visual>
          <collision name='standoff_8in_0_collision'>
            <pose frame=''>0.06764 0.13142 0.20228 0 -0 0</pose>
            <geometry>
              <cylinder>
                <radius>0.011113</radius>
                <length>0.2032</length>
              </cylinder>
            </geometry>
            <max_contacts>10</max_contacts>
            <surface>
              <contact>
                <ode/>
              </contact>
              <bounce/>
              <friction>
                <torsional>
                  <ode/>
                </torsional>
                <ode/>
              </friction>
            </surface>
          </collision>
          <visual name='standoff_8in_0_visual'>
            <pose frame=''>0.06764 0.13142 0.20228 0 -0 0</pose>
            <geometry>
              <mesh>
                <uri>model://turtlebot/meshes/68-02421-8000-RA_Turtlebot_F-F_Standoff.dae</uri>
              </mesh>
            </geometry>
          </visual>
          <collision name='standoff_8in_1_collision'>
            <pose frame=''>0.06764 -0.13142 0.20228 0 -0 0</pose>
            <geometry>
              <cylinder>
                <radius>0.011113</radius>
                <length>0.2032</length>
              </cylinder>
            </geometry>
            <max_contacts>10</max_contacts>
            <surface>
              <contact>
                <ode/>
              </contact>
              <bounce/>
              <friction>
                <torsional>
                  <ode/>
                </torsional>
                <ode/>
              </friction>
            </surface>
          </collision>
          <visual name='standoff_8in_1_visual'>
            <pose frame=''>0.06764 -0.13142 0.20228 0 -0 0</pose>
            <geometry>
              <mesh>
                <uri>model://turtlebot/meshes/68-02421-8000-RA_Turtlebot_F-F_Standoff.dae</uri>
              </mesh>
            </geometry>
          </visual>
          <collision name='standoff_8in_2_collision'>
            <pose frame=''>-0.052832 -0.13142 0.20228 0 -0 0</pose>
            <geometry>
              <cylinder>
                <radius>0.011113</radius>
                <length>0.2032</length>
              </cylinder>
            </geometry>
            <max_contacts>10</max_contacts>
            <surface>
              <contact>
                <ode/>
              </contact>
              <bounce/>
              <friction>
                <torsional>
                  <ode/>
                </torsional>
                <ode/>
              </friction>
            </surface>
          </collision>
          <visual name='standoff_8in_2_visual'>
            <pose frame=''>-0.052832 -0.13142 0.20228 0 -0 0</pose>
            <geometry>
              <mesh>
                <uri>model://turtlebot/meshes/68-02421-8000-RA_Turtlebot_F-F_Standoff.dae</uri>
              </mesh>
            </geometry>
          </visual>
          <collision name='standoff_8in_3_collision'>
            <pose frame=''>-0.052832 0.13142 0.20228 0 -0 0</pose>
            <geometry>
              <cylinder>
                <radius>0.011113</radius>
                <length>0.2032</length>
              </cylinder>
            </geometry>
            <max_contacts>10</max_contacts>
            <surface>
              <contact>
                <ode/>
              </contact>
              <bounce/>
              <friction>
                <torsional>
                  <ode/>
                </torsional>
                <ode/>
              </friction>
            </surface>
          </collision>
          <visual name='standoff_8in_3_visual'>
            <pose frame=''>-0.052832 0.13142 0.20228 0 -0 0</pose>
            <geometry>
              <mesh>
                <uri>model://turtlebot/meshes/68-02421-8000-RA_Turtlebot_F-F_Standoff.dae</uri>
              </mesh>
            </geometry>
          </visual>
          <collision name='standoff_kinect_0_collision'>
            <pose frame=''>-0.105098 0.098 0.202308 0 -0 0</pose>
            <geometry>
              <cylinder>
                <radius>0.001111</radius>
                <length>0.008585</length>
              </cylinder>
            </geometry>
            <max_contacts>10</max_contacts>
            <surface>
              <contact>
                <ode/>
              </contact>
              <bounce/>
              <friction>
                <torsional>
                  <ode/>
                </torsional>
                <ode/>
              </friction>
            </surface>
          </collision>
          <visual name='standoff_kinect_0_visual'>
            <pose frame=''>-0.105098 0.098 0.202308 0 -0 0</pose>
            <geometry>
              <mesh>
                <uri>model://turtlebot/meshes/68-04556-RA_Kinect_Standoff_Assy.dae</uri>
              </mesh>
            </geometry>
          </visual>
          <collision name='standoff_kinect_1_collision'>
            <pose frame=''>-0.105098 -0.098 0.202308 0 -0 0</pose>
            <geometry>
              <cylinder>
                <radius>0.001111</radius>
                <length>0.008585</length>
              </cylinder>
            </geometry>
            <max_contacts>10</max_contacts>
            <surface>
              <contact>
                <ode/>
              </contact>
              <bounce/>
              <friction>
                <torsional>
                  <ode/>
                </torsional>
                <ode/>
              </friction>
            </surface>
          </collision>
          <visual name='standoff_kinect_1_visual'>
            <pose frame=''>-0.105098 -0.098 0.202308 0 -0 0</pose>
            <geometry>
              <mesh>
                <uri>model://turtlebot/meshes/68-04556-RA_Kinect_Standoff_Assy.dae</uri>
              </mesh>
            </geometry>
          </visual>
          <sensor name='laser' type='ray'>
            <pose frame=''>-0.065 0 0.092 0 -0 0</pose>
            <ray>
              <scan>
                <horizontal>
                  <samples>180</samples>
                  <resolution>1</resolution>
                  <min_angle>-2.26893</min_angle>
                  <max_angle>2.26893</max_angle>
                </horizontal>
                <vertical>
                  <samples>1</samples>
                  <min_angle>0</min_angle>
                  <max_angle>0</max_angle>
                </vertical>
              </scan>
              <range>
                <min>0.08</min>
                <max>10</max>
                <resolution>0.01</resolution>
              </range>
            </ray>
            <update_rate>20</update_rate>
          </sensor>
          <self_collide>0</self_collide>
          <kinematic>0</kinematic>
          <gravity>1</gravity>
        </link>
        <link name='create::base'>
          <inertial>
            <pose frame=''>0.001453 -0.000453 0.029787 0 -0 0</pose>
            <inertia>
              <ixx>0.05864</ixx>
              <ixy>0.000124</ixy>
              <ixz>0.000615</ixz>
              <iyy>0.058786</iyy>
              <iyz>1.4e-05</iyz>
              <izz>1.53244</izz>
            </inertia>
            <mass>2.234</mass>
          </inertial>
          <collision name='base_collision'>
            <pose frame=''>0 0 0.0478 0 -0 0</pose>
            <geometry>
              <cylinder>
                <radius>0.016495</radius>
                <length>0.061163</length>
              </cylinder>
            </geometry>
            <max_contacts>10</max_contacts>
            <surface>
              <contact>
                <ode/>
              </contact>
              <bounce/>
              <friction>
                <torsional>
                  <ode/>
                </torsional>
                <ode/>
              </friction>
            </surface>
          </collision>
          <visual name='base_visual'>
            <pose frame=''>0 0 0.0478 0 -0 0</pose>
            <geometry>
              <mesh>
                <uri>model://create/meshes/create_body.dae</uri>
              </mesh>
            </geometry>
          </visual>
          <collision name='front_wheel_collision'>
            <pose frame=''>0.13 0 0.017 -0 1.5707 1.5707</pose>
            <geometry>
              <sphere>
                <radius>0.018</radius>
              </sphere>
            </geometry>
            <surface>
              <friction>
                <ode>
                  <mu>0</mu>
                  <mu2>0</mu2>
                  <fdir1>0 0 0</fdir1>
                  <slip1>0</slip1>
                  <slip2>0</slip2>
                </ode>
                <torsional>
                  <ode/>
                </torsional>
              </friction>
              <contact>
                <ode/>
              </contact>
              <bounce/>
            </surface>
            <max_contacts>10</max_contacts>
          </collision>
          <visual name='front_wheel_visual'>
            <pose frame=''>0.13 0 0.017 -0 1.5707 1.5707</pose>
            <geometry>
              <sphere>
                <radius>0.009</radius>
              </sphere>
            </geometry>
          </visual>
          <collision name='rear_wheel_collision'>
            <pose frame=''>-0.13 0 0.017 -0 1.5707 1.5707</pose>
            <geometry>
              <sphere>
                <radius>0.015</radius>
              </sphere>
            </geometry>
            <surface>
              <friction>
                <ode>
                  <mu>0</mu>
                  <mu2>0</mu2>
                  <fdir1>0 0 0</fdir1>
                  <slip1>0</slip1>
                  <slip2>0</slip2>
                </ode>
                <torsional>
                  <ode/>
                </torsional>
              </friction>
              <contact>
                <ode/>
              </contact>
              <bounce/>
            </surface>
            <max_contacts>10</max_contacts>
          </collision>
          <visual name='rear_wheel_visual'>
            <pose frame=''>-0.13 0 0.017 -0 1.5707 1.5707</pose>
            <geometry>
              <sphere>
                <radius>0.0075</radius>
              </sphere>
            </geometry>
          </visual>
          <sensor name='left_cliff_sensor' type='ray'>
            <pose frame=''>0.07 0.14 0.027 0 1.57079 0</pose>
            <ray>
              <scan>
                <horizontal>
                  <samples>1</samples>
                  <resolution>1</resolution>
                  <min_angle>0</min_angle>
                  <max_angle>0</max_angle>
                </horizontal>
                <vertical>
                  <samples>1</samples>
                  <min_angle>0</min_angle>
                  <max_angle>0</max_angle>
                </vertical>
              </scan>
              <range>
                <min>0.01</min>
                <max>0.04</max>
                <resolution>0.1</resolution>
              </range>
            </ray>
          </sensor>
          <sensor name='leftfront_cliff_sensor' type='ray'>
            <pose frame=''>0.15 0.04 0.027 0 1.57079 0</pose>
            <ray>
              <scan>
                <horizontal>
                  <samples>1</samples>
                  <resolution>1</resolution>
                  <min_angle>0</min_angle>
                  <max_angle>0</max_angle>
                </horizontal>
                <vertical>
                  <samples>1</samples>
                  <min_angle>0</min_angle>
                  <max_angle>0</max_angle>
                </vertical>
              </scan>
              <range>
                <min>0.01</min>
                <max>0.04</max>
                <resolution>0.1</resolution>
              </range>
            </ray>
          </sensor>
          <sensor name='right_cliff_sensor' type='ray'>
            <pose frame=''>0.07 -0.14 0.027 0 1.57079 0</pose>
            <ray>
              <scan>
                <horizontal>
                  <samples>1</samples>
                  <resolution>1</resolution>
                  <min_angle>0</min_angle>
                  <max_angle>0</max_angle>
                </horizontal>
                <vertical>
                  <samples>1</samples>
                  <min_angle>0</min_angle>
                  <max_angle>0</max_angle>
                </vertical>
              </scan>
              <range>
                <min>0.01</min>
                <max>0.04</max>
                <resolution>0.1</resolution>
              </range>
            </ray>
          </sensor>
          <sensor name='rightfront_cliff_sensor' type='ray'>
            <pose frame=''>0.15 -0.04 0.027 0 1.57079 0</pose>
            <ray>
              <scan>
                <horizontal>
                  <samples>1</samples>
                  <resolution>1</resolution>
                  <min_angle>0</min_angle>
                  <max_angle>0</max_angle>
                </horizontal>
                <vertical>
                  <samples>1</samples>
                  <min_angle>0</min_angle>
                  <max_angle>0</max_angle>
                </vertical>
              </scan>
              <range>
                <min>0.01</min>
                <max>0.04</max>
                <resolution>0.1</resolution>
              </range>
            </ray>
          </sensor>
          <sensor name='wall_sensor' type='ray'>
            <pose frame=''>0.09 -0.12 0.059 0 0 -1</pose>
            <ray>
              <scan>
                <horizontal>
                  <samples>1</samples>
                  <resolution>1</resolution>
                  <min_angle>0</min_angle>
                  <max_angle>0</max_angle>
                </horizontal>
                <vertical>
                  <samples>1</samples>
                  <min_angle>0</min_angle>
                  <max_angle>0</max_angle>
                </vertical>
              </scan>
              <range>
                <min>0.016</min>
                <max>0.04</max>
                <resolution>0.1</resolution>
              </range>
            </ray>
          </sensor>
          <pose frame=''>0 0 0 0 -0 0</pose>
          <self_collide>0</self_collide>
          <kinematic>0</kinematic>
          <gravity>1</gravity>
        </link>
        <link name='create::left_wheel'>
          <pose frame=''>0 0.13 0.032 0 -0 0</pose>
          <inertial>
            <inertia>
              <ixx>0.001</ixx>
              <ixy>0</ixy>
              <ixz>0</ixz>
              <iyy>0.001</iyy>
              <iyz>0</iyz>
              <izz>0.001</izz>
            </inertia>
            <mass>0.01</mass>
          </inertial>
          <collision name='collision'>
            <pose frame=''>0 0 0 -0 1.5707 1.5707</pose>
            <geometry>
              <cylinder>
                <radius>0.033</radius>
                <length>0.023</length>
              </cylinder>
            </geometry>
            <surface>
              <friction>
                <ode>
                  <mu>10</mu>
                  <mu2>10</mu2>
                  <fdir1>0 0 0</fdir1>
                  <slip1>0</slip1>
                  <slip2>0</slip2>
                </ode>
                <torsional>
                  <ode/>
                </torsional>
              </friction>
              <contact>
                <ode/>
              </contact>
              <bounce/>
            </surface>
            <max_contacts>10</max_contacts>
          </collision>
          <visual name='visual'>
            <pose frame=''>0 0 0 -0 1.5707 1.5707</pose>
            <geometry>
              <cylinder>
                <radius>0.033</radius>
                <length>0.023</length>
              </cylinder>
            </geometry>
          </visual>
          <self_collide>0</self_collide>
          <kinematic>0</kinematic>
          <gravity>1</gravity>
        </link>
        <link name='create::right_wheel'>
          <pose frame=''>0 -0.13 0.032 0 -0 0</pose>
          <inertial>
            <inertia>
              <ixx>0.001</ixx>
              <ixy>0</ixy>
              <ixz>0</ixz>
              <iyy>0.001</iyy>
              <iyz>0</iyz>
              <izz>0.001</izz>
            </inertia>
            <mass>0.01</mass>
          </inertial>
          <collision name='collision'>
            <pose frame=''>0 0 0 -0 1.5707 1.5707</pose>
            <geometry>
              <cylinder>
                <radius>0.033</radius>
                <length>0.023</length>
              </cylinder>
            </geometry>
            <surface>
              <friction>
                <ode>
                  <mu>10</mu>
                  <mu2>10</mu2>
                  <fdir1>0 0 0</fdir1>
                  <slip1>0</slip1>
                  <slip2>0</slip2>
                </ode>
                <torsional>
                  <ode/>
                </torsional>
              </friction>
              <contact>
                <ode/>
              </contact>
              <bounce/>
            </surface>
            <max_contacts>10</max_contacts>
          </collision>
          <visual name='visual'>
            <pose frame=''>0 0 0 -0 1.5707 1.5707</pose>
            <geometry>
              <cylinder>
                <radius>0.033</radius>
                <length>0.023</length>
              </cylinder>
            </geometry>
          </visual>
          <self_collide>0</self_collide>
          <kinematic>0</kinematic>
          <gravity>1</gravity>
        </link>
        <joint name='create::left_wheel' type='revolute'>
          <parent>create::base</parent>
          <child>create::left_wheel</child>
          <axis>
            <xyz>0 1 0</xyz>
            <use_parent_model_frame>1</use_parent_model_frame>
            <limit>
              <lower>-1e+16</lower>
              <upper>1e+16</upper>
            </limit>
            <dynamics>
              <spring_reference>0</spring_reference>
              <spring_stiffness>0</spring_stiffness>
            </dynamics>
          </axis>
        </joint>
        <joint name='create::right_wheel' type='revolute'>
          <parent>create::base</parent>
          <child>create::right_wheel</child>
          <axis>
            <xyz>0 1 0</xyz>
            <use_parent_model_frame>1</use_parent_model_frame>
            <limit>
              <lower>-1e+16</lower>
              <upper>1e+16</upper>
            </limit>
            <dynamics>
              <spring_reference>0</spring_reference>
              <spring_stiffness>0</spring_stiffness>
            </dynamics>
          </axis>
        </joint>
        <link name='kinect::link'>
          <inertial>
            <mass>0.1</mass>
            <inertia>
              <ixx>1</ixx>
              <ixy>0</ixy>
              <ixz>0</ixz>
              <iyy>1</iyy>
              <iyz>0</iyz>
              <izz>1</izz>
            </inertia>
          </inertial>
          <collision name='collision'>
            <geometry>
              <box>
                <size>0.073 0.276 0.072</size>
              </box>
            </geometry>
            <max_contacts>10</max_contacts>
            <surface>
              <contact>
                <ode/>
              </contact>
              <bounce/>
              <friction>
                <torsional>
                  <ode/>
                </torsional>
                <ode/>
              </friction>
            </surface>
          </collision>
          <visual name='visual'>
            <geometry>
              <mesh>
                <uri>model://kinect/meshes/kinect.dae</uri>
              </mesh>
            </geometry>
          </visual>
          <sensor name='camera' type='depth'>
            <update_rate>20</update_rate>
            <camera name='__default__'>
              <horizontal_fov>1.0472</horizontal_fov>
              <image>
                <width>640</width>
                <height>480</height>
                <format>R8G8B8</format>
              </image>
              <clip>
                <near>0.05</near>
                <far>3</far>
              </clip>
            </camera>
          </sensor>
          <pose frame=''>-0.087098 0 0.303857 0 -0 0</pose>
          <self_collide>0</self_collide>
          <kinematic>0</kinematic>
          <gravity>1</gravity>
        </link>
        <joint name='create_rack' type='revolute'>
          <parent>create::base</parent>
          <child>rack</child>
          <axis>
            <xyz>0 0 1</xyz>
            <limit>
              <lower>0</lower>
              <upper>0</upper>
            </limit>
            <use_parent_model_frame>1</use_parent_model_frame>
            <dynamics>
              <spring_reference>0</spring_reference>
              <spring_stiffness>0</spring_stiffness>
            </dynamics>
          </axis>
        </joint>
        <joint name='kinect_rack' type='revolute'>
          <parent>kinect::link</parent>
          <child>rack</child>
          <axis>
            <xyz>0 0 1</xyz>
            <limit>
              <lower>0</lower>
              <upper>0</upper>
            </limit>
            <use_parent_model_frame>1</use_parent_model_frame>
            <dynamics>
              <spring_reference>0</spring_reference>
              <spring_stiffness>0</spring_stiffness>
            </dynamics>
          </axis>
        </joint>
        <pose frame=''>1.67771 3.50486 0 0 -0 0</pose>
      </model>
      <model name='turtlebot_0'>
        <link name='rack'>
          <inertial>
            <pose frame=''>0.001453 -0.000453 0.029787 0 -0 0</pose>
            <inertia>
              <ixx>0.05864</ixx>
              <ixy>0.000124</ixy>
              <ixz>0.000615</ixz>
              <iyy>0.058786</iyy>
              <iyz>1.4e-05</iyz>
              <izz>1.53244</izz>
            </inertia>
            <mass>2.234</mass>
          </inertial>
          <collision name='plate_0_collision'>
            <pose frame=''>-0.04334 0 0.084757 0 -0 0</pose>
            <geometry>
              <box>
                <size>0.233502 0.314845 0.006401</size>
              </box>
            </geometry>
            <max_contacts>10</max_contacts>
            <surface>
              <contact>
                <ode/>
              </contact>
              <bounce/>
              <friction>
                <torsional>
                  <ode/>
                </torsional>
                <ode/>
              </friction>
            </surface>
          </collision>
          <visual name='plate_0_visual'>
            <pose frame=''>-0.04334 0 0.084757 0 -0 0</pose>
            <geometry>
              <mesh>
                <uri>model://turtlebot/meshes/plate_0_logo.dae</uri>
              </mesh>
            </geometry>
          </visual>
          <collision name='plate_1_collision'>
            <pose frame=''>-0.00266 0 0.141907 0 -0 0</pose>
            <geometry>
              <box>
                <size>0.314856 0.314856 0.006401</size>
              </box>
            </geometry>
            <max_contacts>10</max_contacts>
            <surface>
              <contact>
                <ode/>
              </contact>
              <bounce/>
              <friction>
                <torsional>
                  <ode/>
                </torsional>
                <ode/>
              </friction>
            </surface>
          </collision>
          <visual name='plate_1_visual'>
            <pose frame=''>-0.00266 0 0.141907 0 -0 0</pose>
            <geometry>
              <mesh>
                <uri>model://turtlebot/meshes/plate_1_logo.dae</uri>
              </mesh>
            </geometry>
          </visual>
          <collision name='plate_2_collision'>
            <pose frame=''>-0.00266 0 0.199108 0 -0 0</pose>
            <geometry>
              <box>
                <size>0.314856 0.314856 0.006401</size>
              </box>
            </geometry>
            <max_contacts>10</max_contacts>
            <surface>
              <contact>
                <ode/>
              </contact>
              <bounce/>
              <friction>
                <torsional>
                  <ode/>
                </torsional>
                <ode/>
              </friction>
            </surface>
          </collision>
          <visual name='plate_2_visual'>
            <pose frame=''>-0.00266 0 0.199108 0 -0 0</pose>
            <geometry>
              <mesh>
                <uri>model://turtlebot/meshes/plate_1_logo.dae</uri>
              </mesh>
            </geometry>
          </visual>
          <collision name='plate_3_collision'>
            <pose frame=''>-0.01582 0 0.405457 0 -0 0</pose>
            <geometry>
              <box>
                <size>0.288 0.315 0.006401</size>
              </box>
            </geometry>
            <max_contacts>10</max_contacts>
            <surface>
              <contact>
                <ode/>
              </contact>
              <bounce/>
              <friction>
                <torsional>
                  <ode/>
                </torsional>
                <ode/>
              </friction>
            </surface>
          </collision>
          <visual name='plate_3_visual'>
            <pose frame=''>-0.01582 0 0.405457 0 -0 0</pose>
            <geometry>
              <mesh>
                <uri>model://turtlebot/meshes/plate_2_logo.dae</uri>
              </mesh>
            </geometry>
          </visual>
          <collision name='spacer_0_collision'>
            <pose frame=''>-0.00254 0.111468 0.079992 0 -0 0</pose>
            <geometry>
              <cylinder>
                <radius>0.0127</radius>
                <length>0.003175</length>
              </cylinder>
            </geometry>
            <max_contacts>10</max_contacts>
            <surface>
              <contact>
                <ode/>
              </contact>
              <bounce/>
              <friction>
                <torsional>
                  <ode/>
                </torsional>
                <ode/>
              </friction>
            </surface>
          </collision>
          <visual name='spacer_0_visual'>
            <pose frame=''>-0.00254 0.111468 0.079992 0 -0 0</pose>
            <geometry>
              <mesh>
                <uri>model://turtlebot/meshes/68-02403-125_Spacer.dae</uri>
              </mesh>
            </geometry>
          </visual>
          <collision name='spacer_1_collision'>
            <pose frame=''>-0.00254 -0.111468 0.079992 0 -0 0</pose>
            <geometry>
              <cylinder>
                <radius>0.0127</radius>
                <length>0.003175</length>
              </cylinder>
            </geometry>
            <max_contacts>10</max_contacts>
            <surface>
              <contact>
                <ode/>
              </contact>
              <bounce/>
              <friction>
                <torsional>
                  <ode/>
                </torsional>
                <ode/>
              </friction>
            </surface>
          </collision>
          <visual name='spacer_1_visual'>
            <pose frame=''>-0.00254 -0.111468 0.079992 0 -0 0</pose>
            <geometry>
              <mesh>
                <uri>model://turtlebot/meshes/68-02403-125_Spacer.dae</uri>
              </mesh>
            </geometry>
          </visual>
          <collision name='spacer_2_collision'>
            <pose frame=''>-0.07239 -0.111468 0.079992 0 -0 0</pose>
            <geometry>
              <cylinder>
                <radius>0.0127</radius>
                <length>0.003175</length>
              </cylinder>
            </geometry>
            <max_contacts>10</max_contacts>
            <surface>
              <contact>
                <ode/>
              </contact>
              <bounce/>
              <friction>
                <torsional>
                  <ode/>
                </torsional>
                <ode/>
              </friction>
            </surface>
          </collision>
          <visual name='spacer_2_visual'>
            <pose frame=''>-0.07239 -0.111468 0.079992 0 -0 0</pose>
            <geometry>
              <mesh>
                <uri>model://turtlebot/meshes/68-02403-125_Spacer.dae</uri>
              </mesh>
            </geometry>
          </visual>
          <collision name='spacer_3_collision'>
            <pose frame=''>-0.07239 0.111468 0.079992 0 -0 0</pose>
            <geometry>
              <cylinder>
                <radius>0.0127</radius>
                <length>0.003175</length>
              </cylinder>
            </geometry>
            <max_contacts>10</max_contacts>
            <surface>
              <contact>
                <ode/>
              </contact>
              <bounce/>
              <friction>
                <torsional>
                  <ode/>
                </torsional>
                <ode/>
              </friction>
            </surface>
          </collision>
          <visual name='spacer_3_visual'>
            <pose frame=''>-0.07239 0.111468 0.079992 0 -0 0</pose>
            <geometry>
              <mesh>
                <uri>model://turtlebot/meshes/68-02403-125_Spacer.dae</uri>
              </mesh>
            </geometry>
          </visual>
          <collision name='standoff_2in_0_collision'>
            <pose frame=''>0.06764 0.13142 0.08798 0 -0 0</pose>
            <geometry>
              <cylinder>
                <radius>0.0381</radius>
                <length>0.0635</length>
              </cylinder>
            </geometry>
            <max_contacts>10</max_contacts>
            <surface>
              <contact>
                <ode/>
              </contact>
              <bounce/>
              <friction>
                <torsional>
                  <ode/>
                </torsional>
                <ode/>
              </friction>
            </surface>
          </collision>
          <visual name='standoff_2in_0_visual'>
            <pose frame=''>0.06764 0.13142 0.08798 0 -0 0</pose>
            <geometry>
              <mesh>
                <uri>model://turtlebot/meshes/68-04552-2000-RA_Turtlebot_M-F_Standoff.dae</uri>
              </mesh>
            </geometry>
          </visual>
          <collision name='standoff_2in_1_collision'>
            <pose frame=''>0.06764 -0.13142 0.08798 0 -0 0</pose>
            <geometry>
              <cylinder>
                <radius>0.0381</radius>
                <length>0.0635</length>
              </cylinder>
            </geometry>
            <max_contacts>10</max_contacts>
            <surface>
              <contact>
                <ode/>
              </contact>
              <bounce/>
              <friction>
                <torsional>
                  <ode/>
                </torsional>
                <ode/>
              </friction>
            </surface>
          </collision>
          <visual name='standoff_2in_1_visual'>
            <pose frame=''>0.06764 -0.13142 0.08798 0 -0 0</pose>
            <geometry>
              <mesh>
                <uri>model://turtlebot/meshes/68-04552-2000-RA_Turtlebot_M-F_Standoff.dae</uri>
              </mesh>
            </geometry>
          </visual>
          <collision name='standoff_2in_2_collision'>
            <pose frame=''>-0.052832 -0.13142 0.08798 0 -0 0</pose>
            <geometry>
              <cylinder>
                <radius>0.0381</radius>
                <length>0.0635</length>
              </cylinder>
            </geometry>
            <max_contacts>10</max_contacts>
            <surface>
              <contact>
                <ode/>
              </contact>
              <bounce/>
              <friction>
                <torsional>
                  <ode/>
                </torsional>
                <ode/>
              </friction>
            </surface>
          </collision>
          <visual name='standoff_2in_2_visual'>
            <pose frame=''>-0.052832 -0.13142 0.08798 0 -0 0</pose>
            <geometry>
              <mesh>
                <uri>model://turtlebot/meshes/68-04552-2000-RA_Turtlebot_M-F_Standoff.dae</uri>
              </mesh>
            </geometry>
          </visual>
          <collision name='standoff_2in_3_collision'>
            <pose frame=''>-0.052832 0.13142 0.08798 0 -0 0</pose>
            <geometry>
              <cylinder>
                <radius>0.0381</radius>
                <length>0.0635</length>
              </cylinder>
            </geometry>
            <max_contacts>10</max_contacts>
            <surface>
              <contact>
                <ode/>
              </contact>
              <bounce/>
              <friction>
                <torsional>
                  <ode/>
                </torsional>
                <ode/>
              </friction>
            </surface>
          </collision>
          <visual name='standoff_2in_3_visual'>
            <pose frame=''>-0.052832 0.13142 0.08798 0 -0 0</pose>
            <geometry>
              <mesh>
                <uri>model://turtlebot/meshes/68-04552-2000-RA_Turtlebot_M-F_Standoff.dae</uri>
              </mesh>
            </geometry>
          </visual>
          <collision name='standoff_2in_4_collision'>
            <pose frame=''>0.06764 0.13142 0.14513 0 -0 0</pose>
            <geometry>
              <cylinder>
                <radius>0.0381</radius>
                <length>0.0635</length>
              </cylinder>
            </geometry>
            <max_contacts>10</max_contacts>
            <surface>
              <contact>
                <ode/>
              </contact>
              <bounce/>
              <friction>
                <torsional>
                  <ode/>
                </torsional>
                <ode/>
              </friction>
            </surface>
          </collision>
          <visual name='standoff_2in_4_visual'>
            <pose frame=''>0.06764 0.13142 0.14513 0 -0 0</pose>
            <geometry>
              <mesh>
                <uri>model://turtlebot/meshes/68-04552-2000-RA_Turtlebot_M-F_Standoff.dae</uri>
              </mesh>
            </geometry>
          </visual>
          <collision name='standoff_2in_5_collision'>
            <pose frame=''>0.06764 -0.13142 0.14513 0 -0 0</pose>
            <geometry>
              <cylinder>
                <radius>0.0381</radius>
                <length>0.0635</length>
              </cylinder>
            </geometry>
            <max_contacts>10</max_contacts>
            <surface>
              <contact>
                <ode/>
              </contact>
              <bounce/>
              <friction>
                <torsional>
                  <ode/>
                </torsional>
                <ode/>
              </friction>
            </surface>
          </collision>
          <visual name='standoff_2in_5_visual'>
            <pose frame=''>0.06764 -0.13142 0.14513 0 -0 0</pose>
            <geometry>
              <mesh>
                <uri>model://turtlebot/meshes/68-04552-2000-RA_Turtlebot_M-F_Standoff.dae</uri>
              </mesh>
            </geometry>
          </visual>
          <collision name='standoff_2in_6_collision'>
            <pose frame=''>-0.052832 -0.13142 0.14513 0 -0 0</pose>
            <geometry>
              <cylinder>
                <radius>0.0381</radius>
                <length>0.0635</length>
              </cylinder>
            </geometry>
            <max_contacts>10</max_contacts>
            <surface>
              <contact>
                <ode/>
              </contact>
              <bounce/>
              <friction>
                <torsional>
                  <ode/>
                </torsional>
                <ode/>
              </friction>
            </surface>
          </collision>
          <visual name='standoff_2in_6_visual'>
            <pose frame=''>-0.052832 -0.13142 0.14513 0 -0 0</pose>
            <geometry>
              <mesh>
                <uri>model://turtlebot/meshes/68-04552-2000-RA_Turtlebot_M-F_Standoff.dae</uri>
              </mesh>
            </geometry>
          </visual>
          <collision name='standoff_2in_7_collision'>
            <pose frame=''>-0.052832 0.13142 0.14513 0 -0 0</pose>
            <geometry>
              <cylinder>
                <radius>0.0381</radius>
                <length>0.0635</length>
              </cylinder>
            </geometry>
            <max_contacts>10</max_contacts>
            <surface>
              <contact>
                <ode/>
              </contact>
              <bounce/>
              <friction>
                <torsional>
                  <ode/>
                </torsional>
                <ode/>
              </friction>
            </surface>
          </collision>
          <visual name='standoff_2in_7_visual'>
            <pose frame=''>-0.052832 0.13142 0.14513 0 -0 0</pose>
            <geometry>
              <mesh>
                <uri>model://turtlebot/meshes/68-04552-2000-RA_Turtlebot_M-F_Standoff.dae</uri>
              </mesh>
            </geometry>
          </visual>
          <collision name='standoff_8in_0_collision'>
            <pose frame=''>0.06764 0.13142 0.20228 0 -0 0</pose>
            <geometry>
              <cylinder>
                <radius>0.011113</radius>
                <length>0.2032</length>
              </cylinder>
            </geometry>
            <max_contacts>10</max_contacts>
            <surface>
              <contact>
                <ode/>
              </contact>
              <bounce/>
              <friction>
                <torsional>
                  <ode/>
                </torsional>
                <ode/>
              </friction>
            </surface>
          </collision>
          <visual name='standoff_8in_0_visual'>
            <pose frame=''>0.06764 0.13142 0.20228 0 -0 0</pose>
            <geometry>
              <mesh>
                <uri>model://turtlebot/meshes/68-02421-8000-RA_Turtlebot_F-F_Standoff.dae</uri>
              </mesh>
            </geometry>
          </visual>
          <collision name='standoff_8in_1_collision'>
            <pose frame=''>0.06764 -0.13142 0.20228 0 -0 0</pose>
            <geometry>
              <cylinder>
                <radius>0.011113</radius>
                <length>0.2032</length>
              </cylinder>
            </geometry>
            <max_contacts>10</max_contacts>
            <surface>
              <contact>
                <ode/>
              </contact>
              <bounce/>
              <friction>
                <torsional>
                  <ode/>
                </torsional>
                <ode/>
              </friction>
            </surface>
          </collision>
          <visual name='standoff_8in_1_visual'>
            <pose frame=''>0.06764 -0.13142 0.20228 0 -0 0</pose>
            <geometry>
              <mesh>
                <uri>model://turtlebot/meshes/68-02421-8000-RA_Turtlebot_F-F_Standoff.dae</uri>
              </mesh>
            </geometry>
          </visual>
          <collision name='standoff_8in_2_collision'>
            <pose frame=''>-0.052832 -0.13142 0.20228 0 -0 0</pose>
            <geometry>
              <cylinder>
                <radius>0.011113</radius>
                <length>0.2032</length>
              </cylinder>
            </geometry>
            <max_contacts>10</max_contacts>
            <surface>
              <contact>
                <ode/>
              </contact>
              <bounce/>
              <friction>
                <torsional>
                  <ode/>
                </torsional>
                <ode/>
              </friction>
            </surface>
          </collision>
          <visual name='standoff_8in_2_visual'>
            <pose frame=''>-0.052832 -0.13142 0.20228 0 -0 0</pose>
            <geometry>
              <mesh>
                <uri>model://turtlebot/meshes/68-02421-8000-RA_Turtlebot_F-F_Standoff.dae</uri>
              </mesh>
            </geometry>
          </visual>
          <collision name='standoff_8in_3_collision'>
            <pose frame=''>-0.052832 0.13142 0.20228 0 -0 0</pose>
            <geometry>
              <cylinder>
                <radius>0.011113</radius>
                <length>0.2032</length>
              </cylinder>
            </geometry>
            <max_contacts>10</max_contacts>
            <surface>
              <contact>
                <ode/>
              </contact>
              <bounce/>
              <friction>
                <torsional>
                  <ode/>
                </torsional>
                <ode/>
              </friction>
            </surface>
          </collision>
          <visual name='standoff_8in_3_visual'>
            <pose frame=''>-0.052832 0.13142 0.20228 0 -0 0</pose>
            <geometry>
              <mesh>
                <uri>model://turtlebot/meshes/68-02421-8000-RA_Turtlebot_F-F_Standoff.dae</uri>
              </mesh>
            </geometry>
          </visual>
          <collision name='standoff_kinect_0_collision'>
            <pose frame=''>-0.105098 0.098 0.202308 0 -0 0</pose>
            <geometry>
              <cylinder>
                <radius>0.001111</radius>
                <length>0.008585</length>
              </cylinder>
            </geometry>
            <max_contacts>10</max_contacts>
            <surface>
              <contact>
                <ode/>
              </contact>
              <bounce/>
              <friction>
                <torsional>
                  <ode/>
                </torsional>
                <ode/>
              </friction>
            </surface>
          </collision>
          <visual name='standoff_kinect_0_visual'>
            <pose frame=''>-0.105098 0.098 0.202308 0 -0 0</pose>
            <geometry>
              <mesh>
                <uri>model://turtlebot/meshes/68-04556-RA_Kinect_Standoff_Assy.dae</uri>
              </mesh>
            </geometry>
          </visual>
          <collision name='standoff_kinect_1_collision'>
            <pose frame=''>-0.105098 -0.098 0.202308 0 -0 0</pose>
            <geometry>
              <cylinder>
                <radius>0.001111</radius>
                <length>0.008585</length>
              </cylinder>
            </geometry>
            <max_contacts>10</max_contacts>
            <surface>
              <contact>
                <ode/>
              </contact>
              <bounce/>
              <friction>
                <torsional>
                  <ode/>
                </torsional>
                <ode/>
              </friction>
            </surface>
          </collision>
          <visual name='standoff_kinect_1_visual'>
            <pose frame=''>-0.105098 -0.098 0.202308 0 -0 0</pose>
            <geometry>
              <mesh>
                <uri>model://turtlebot/meshes/68-04556-RA_Kinect_Standoff_Assy.dae</uri>
              </mesh>
            </geometry>
          </visual>
          <sensor name='laser' type='ray'>
            <pose frame=''>-0.065 0 0.092 0 -0 0</pose>
            <ray>
              <scan>
                <horizontal>
                  <samples>180</samples>
                  <resolution>1</resolution>
                  <min_angle>-2.26893</min_angle>
                  <max_angle>2.26893</max_angle>
                </horizontal>
                <vertical>
                  <samples>1</samples>
                  <min_angle>0</min_angle>
                  <max_angle>0</max_angle>
                </vertical>
              </scan>
              <range>
                <min>0.08</min>
                <max>10</max>
                <resolution>0.01</resolution>
              </range>
            </ray>
            <update_rate>20</update_rate>
          </sensor>
          <self_collide>0</self_collide>
          <kinematic>0</kinematic>
          <gravity>1</gravity>
        </link>
        <link name='create::base'>
          <inertial>
            <pose frame=''>0.001453 -0.000453 0.029787 0 -0 0</pose>
            <inertia>
              <ixx>0.05864</ixx>
              <ixy>0.000124</ixy>
              <ixz>0.000615</ixz>
              <iyy>0.058786</iyy>
              <iyz>1.4e-05</iyz>
              <izz>1.53244</izz>
            </inertia>
            <mass>2.234</mass>
          </inertial>
          <collision name='base_collision'>
            <pose frame=''>0 0 0.0478 0 -0 0</pose>
            <geometry>
              <cylinder>
                <radius>0.016495</radius>
                <length>0.061163</length>
              </cylinder>
            </geometry>
            <max_contacts>10</max_contacts>
            <surface>
              <contact>
                <ode/>
              </contact>
              <bounce/>
              <friction>
                <torsional>
                  <ode/>
                </torsional>
                <ode/>
              </friction>
            </surface>
          </collision>
          <visual name='base_visual'>
            <pose frame=''>0 0 0.0478 0 -0 0</pose>
            <geometry>
              <mesh>
                <uri>model://create/meshes/create_body.dae</uri>
              </mesh>
            </geometry>
          </visual>
          <collision name='front_wheel_collision'>
            <pose frame=''>0.13 0 0.017 -0 1.5707 1.5707</pose>
            <geometry>
              <sphere>
                <radius>0.018</radius>
              </sphere>
            </geometry>
            <surface>
              <friction>
                <ode>
                  <mu>0</mu>
                  <mu2>0</mu2>
                  <fdir1>0 0 0</fdir1>
                  <slip1>0</slip1>
                  <slip2>0</slip2>
                </ode>
                <torsional>
                  <ode/>
                </torsional>
              </friction>
              <contact>
                <ode/>
              </contact>
              <bounce/>
            </surface>
            <max_contacts>10</max_contacts>
          </collision>
          <visual name='front_wheel_visual'>
            <pose frame=''>0.13 0 0.017 -0 1.5707 1.5707</pose>
            <geometry>
              <sphere>
                <radius>0.009</radius>
              </sphere>
            </geometry>
          </visual>
          <collision name='rear_wheel_collision'>
            <pose frame=''>-0.13 0 0.017 -0 1.5707 1.5707</pose>
            <geometry>
              <sphere>
                <radius>0.015</radius>
              </sphere>
            </geometry>
            <surface>
              <friction>
                <ode>
                  <mu>0</mu>
                  <mu2>0</mu2>
                  <fdir1>0 0 0</fdir1>
                  <slip1>0</slip1>
                  <slip2>0</slip2>
                </ode>
                <torsional>
                  <ode/>
                </torsional>
              </friction>
              <contact>
                <ode/>
              </contact>
              <bounce/>
            </surface>
            <max_contacts>10</max_contacts>
          </collision>
          <visual name='rear_wheel_visual'>
            <pose frame=''>-0.13 0 0.017 -0 1.5707 1.5707</pose>
            <geometry>
              <sphere>
                <radius>0.0075</radius>
              </sphere>
            </geometry>
          </visual>
          <sensor name='left_cliff_sensor' type='ray'>
            <pose frame=''>0.07 0.14 0.027 0 1.57079 0</pose>
            <ray>
              <scan>
                <horizontal>
                  <samples>1</samples>
                  <resolution>1</resolution>
                  <min_angle>0</min_angle>
                  <max_angle>0</max_angle>
                </horizontal>
                <vertical>
                  <samples>1</samples>
                  <min_angle>0</min_angle>
                  <max_angle>0</max_angle>
                </vertical>
              </scan>
              <range>
                <min>0.01</min>
                <max>0.04</max>
                <resolution>0.1</resolution>
              </range>
            </ray>
          </sensor>
          <sensor name='leftfront_cliff_sensor' type='ray'>
            <pose frame=''>0.15 0.04 0.027 0 1.57079 0</pose>
            <ray>
              <scan>
                <horizontal>
                  <samples>1</samples>
                  <resolution>1</resolution>
                  <min_angle>0</min_angle>
                  <max_angle>0</max_angle>
                </horizontal>
                <vertical>
                  <samples>1</samples>
                  <min_angle>0</min_angle>
                  <max_angle>0</max_angle>
                </vertical>
              </scan>
              <range>
                <min>0.01</min>
                <max>0.04</max>
                <resolution>0.1</resolution>
              </range>
            </ray>
          </sensor>
          <sensor name='right_cliff_sensor' type='ray'>
            <pose frame=''>0.07 -0.14 0.027 0 1.57079 0</pose>
            <ray>
              <scan>
                <horizontal>
                  <samples>1</samples>
                  <resolution>1</resolution>
                  <min_angle>0</min_angle>
                  <max_angle>0</max_angle>
                </horizontal>
                <vertical>
                  <samples>1</samples>
                  <min_angle>0</min_angle>
                  <max_angle>0</max_angle>
                </vertical>
              </scan>
              <range>
                <min>0.01</min>
                <max>0.04</max>
                <resolution>0.1</resolution>
              </range>
            </ray>
          </sensor>
          <sensor name='rightfront_cliff_sensor' type='ray'>
            <pose frame=''>0.15 -0.04 0.027 0 1.57079 0</pose>
            <ray>
              <scan>
                <horizontal>
                  <samples>1</samples>
                  <resolution>1</resolution>
                  <min_angle>0</min_angle>
                  <max_angle>0</max_angle>
                </horizontal>
                <vertical>
                  <samples>1</samples>
                  <min_angle>0</min_angle>
                  <max_angle>0</max_angle>
                </vertical>
              </scan>
              <range>
                <min>0.01</min>
                <max>0.04</max>
                <resolution>0.1</resolution>
              </range>
            </ray>
          </sensor>
          <sensor name='wall_sensor' type='ray'>
            <pose frame=''>0.09 -0.12 0.059 0 0 -1</pose>
            <ray>
              <scan>
                <horizontal>
                  <samples>1</samples>
                  <resolution>1</resolution>
                  <min_angle>0</min_angle>
                  <max_angle>0</max_angle>
                </horizontal>
                <vertical>
                  <samples>1</samples>
                  <min_angle>0</min_angle>
                  <max_angle>0</max_angle>
                </vertical>
              </scan>
              <range>
                <min>0.016</min>
                <max>0.04</max>
                <resolution>0.1</resolution>
              </range>
            </ray>
          </sensor>
          <pose frame=''>0 0 0 0 -0 0</pose>
          <self_collide>0</self_collide>
          <kinematic>0</kinematic>
          <gravity>1</gravity>
        </link>
        <link name='create::left_wheel'>
          <pose frame=''>0 0.13 0.032 0 -0 0</pose>
          <inertial>
            <inertia>
              <ixx>0.001</ixx>
              <ixy>0</ixy>
              <ixz>0</ixz>
              <iyy>0.001</iyy>
              <iyz>0</iyz>
              <izz>0.001</izz>
            </inertia>
            <mass>0.01</mass>
          </inertial>
          <collision name='collision'>
            <pose frame=''>0 0 0 -0 1.5707 1.5707</pose>
            <geometry>
              <cylinder>
                <radius>0.033</radius>
                <length>0.023</length>
              </cylinder>
            </geometry>
            <surface>
              <friction>
                <ode>
                  <mu>10</mu>
                  <mu2>10</mu2>
                  <fdir1>0 0 0</fdir1>
                  <slip1>0</slip1>
                  <slip2>0</slip2>
                </ode>
                <torsional>
                  <ode/>
                </torsional>
              </friction>
              <contact>
                <ode/>
              </contact>
              <bounce/>
            </surface>
            <max_contacts>10</max_contacts>
          </collision>
          <visual name='visual'>
            <pose frame=''>0 0 0 -0 1.5707 1.5707</pose>
            <geometry>
              <cylinder>
                <radius>0.033</radius>
                <length>0.023</length>
              </cylinder>
            </geometry>
          </visual>
          <self_collide>0</self_collide>
          <kinematic>0</kinematic>
          <gravity>1</gravity>
        </link>
        <link name='create::right_wheel'>
          <pose frame=''>0 -0.13 0.032 0 -0 0</pose>
          <inertial>
            <inertia>
              <ixx>0.001</ixx>
              <ixy>0</ixy>
              <ixz>0</ixz>
              <iyy>0.001</iyy>
              <iyz>0</iyz>
              <izz>0.001</izz>
            </inertia>
            <mass>0.01</mass>
          </inertial>
          <collision name='collision'>
            <pose frame=''>0 0 0 -0 1.5707 1.5707</pose>
            <geometry>
              <cylinder>
                <radius>0.033</radius>
                <length>0.023</length>
              </cylinder>
            </geometry>
            <surface>
              <friction>
                <ode>
                  <mu>10</mu>
                  <mu2>10</mu2>
                  <fdir1>0 0 0</fdir1>
                  <slip1>0</slip1>
                  <slip2>0</slip2>
                </ode>
                <torsional>
                  <ode/>
                </torsional>
              </friction>
              <contact>
                <ode/>
              </contact>
              <bounce/>
            </surface>
            <max_contacts>10</max_contacts>
          </collision>
          <visual name='visual'>
            <pose frame=''>0 0 0 -0 1.5707 1.5707</pose>
            <geometry>
              <cylinder>
                <radius>0.033</radius>
                <length>0.023</length>
              </cylinder>
            </geometry>
          </visual>
          <self_collide>0</self_collide>
          <kinematic>0</kinematic>
          <gravity>1</gravity>
        </link>
        <joint name='create::left_wheel' type='revolute'>
          <parent>create::base</parent>
          <child>create::left_wheel</child>
          <axis>
            <xyz>0 1 0</xyz>
            <use_parent_model_frame>1</use_parent_model_frame>
            <limit>
              <lower>-1e+16</lower>
              <upper>1e+16</upper>
            </limit>
            <dynamics>
              <spring_reference>0</spring_reference>
              <spring_stiffness>0</spring_stiffness>
            </dynamics>
          </axis>
        </joint>
        <joint name='create::right_wheel' type='revolute'>
          <parent>create::base</parent>
          <child>create::right_wheel</child>
          <axis>
            <xyz>0 1 0</xyz>
            <use_parent_model_frame>1</use_parent_model_frame>
            <limit>
              <lower>-1e+16</lower>
              <upper>1e+16</upper>
            </limit>
            <dynamics>
              <spring_reference>0</spring_reference>
              <spring_stiffness>0</spring_stiffness>
            </dynamics>
          </axis>
        </joint>
        <link name='kinect::link'>
          <inertial>
            <mass>0.1</mass>
            <inertia>
              <ixx>1</ixx>
              <ixy>0</ixy>
              <ixz>0</ixz>
              <iyy>1</iyy>
              <iyz>0</iyz>
              <izz>1</izz>
            </inertia>
          </inertial>
          <collision name='collision'>
            <geometry>
              <box>
                <size>0.073 0.276 0.072</size>
              </box>
            </geometry>
            <max_contacts>10</max_contacts>
            <surface>
              <contact>
                <ode/>
              </contact>
              <bounce/>
              <friction>
                <torsional>
                  <ode/>
                </torsional>
                <ode/>
              </friction>
            </surface>
          </collision>
          <visual name='visual'>
            <geometry>
              <mesh>
                <uri>model://kinect/meshes/kinect.dae</uri>
              </mesh>
            </geometry>
          </visual>
          <sensor name='camera' type='depth'>
            <update_rate>20</update_rate>
            <camera name='__default__'>
              <horizontal_fov>1.0472</horizontal_fov>
              <image>
                <width>640</width>
                <height>480</height>
                <format>R8G8B8</format>
              </image>
              <clip>
                <near>0.05</near>
                <far>3</far>
              </clip>
            </camera>
          </sensor>
          <pose frame=''>-0.087098 0 0.303857 0 -0 0</pose>
          <self_collide>0</self_collide>
          <kinematic>0</kinematic>
          <gravity>1</gravity>
        </link>
        <joint name='create_rack' type='revolute'>
          <parent>create::base</parent>
          <child>rack</child>
          <axis>
            <xyz>0 0 1</xyz>
            <limit>
              <lower>0</lower>
              <upper>0</upper>
            </limit>
            <use_parent_model_frame>1</use_parent_model_frame>
            <dynamics>
              <spring_reference>0</spring_reference>
              <spring_stiffness>0</spring_stiffness>
            </dynamics>
          </axis>
        </joint>
        <joint name='kinect_rack' type='revolute'>
          <parent>kinect::link</parent>
          <child>rack</child>
          <axis>
            <xyz>0 0 1</xyz>
            <limit>
              <lower>0</lower>
              <upper>0</upper>
            </limit>
            <use_parent_model_frame>1</use_parent_model_frame>
            <dynamics>
              <spring_reference>0</spring_reference>
              <spring_stiffness>0</spring_stiffness>
            </dynamics>
          </axis>
        </joint>
        <pose frame=''>3.1093 2.50486 0 0 -0 0</pose>
      </model>
      <static>0</static>
      <allow_auto_disable>1</allow_auto_disable>
      <pose frame=''>-2.67771 -2.50486 0 0 -0 0</pose>
    </model>
    <state world_name='default'>
      <sim_time>19 727000000</sim_time>
      <real_time>20 101786683</real_time>
      <wall_time>1554285702 592866663</wall_time>
      <iterations>19727</iterations>
      <model name='Untitled'>
        <pose frame=''>-3.2765 -0.725 0 0 -0 0</pose>
        <scale>1 1 1</scale>
        <link name='Wall_3'>
          <pose frame=''>-1.0265 1.95 0 0 -0 0</pose>
          <velocity>0 0 0 0 -0 0</velocity>
          <acceleration>0 0 0 0 -0 0</acceleration>
          <wrench>0 0 0 0 -0 0</wrench>
        </link>
        <link name='Wall_4'>
          <pose frame=''>2.8985 -0.725 0 0 0 -1.5708</pose>
          <velocity>0 0 0 0 -0 0</velocity>
          <acceleration>0 0 0 0 -0 0</acceleration>
          <wrench>0 0 0 0 -0 0</wrench>
        </link>
        <link name='Wall_5'>
          <pose frame=''>-3.2765 -3.4 0 0 -0 3.14159</pose>
          <velocity>0 0 0 0 -0 0</velocity>
          <acceleration>0 0 0 0 -0 0</acceleration>
          <wrench>0 0 0 0 -0 0</wrench>
        </link>
        <link name='Wall_6'>
          <pose frame=''>-9.4515 -0.725 0 0 -0 1.5708</pose>
          <velocity>0 0 0 0 -0 0</velocity>
          <acceleration>0 0 0 0 -0 0</acceleration>
          <wrench>0 0 0 0 -0 0</wrench>
        </link>
        <link name='Wall_7'>
          <pose frame=''>-7.0265 1.95 0 0 -0 0</pose>
          <velocity>0 0 0 0 -0 0</velocity>
          <acceleration>0 0 0 0 -0 0</acceleration>
          <wrench>0 0 0 0 -0 0</wrench>
        </link>
      </model>
      <model name='Untitled_0'>
        <pose frame=''>-2.67771 -2.50486 0 0 -0 0</pose>
        <scale>1 1 1</scale>
        <model name='House 1'>
          <pose frame=''>9.40809 -3 0 0 -0 0</pose>
          <scale>1 1 1</scale>
          <link name='link'>
            <pose frame=''>9.40809 -3 0 0 -0 0</pose>
            <velocity>0 0 0 0 -0 0</velocity>
            <acceleration>0 0 0 0 -0 0</acceleration>
            <wrench>0 0 0 0 -0 0</wrench>
          </link>
        </model>
        <model name='bookshelf'>
          <pose frame=''>-8.58366 1.53335 0 0 -0 0</pose>
          <scale>1 1 1</scale>
          <link name='link'>
            <pose frame=''>-8.58366 1.53335 0 0 -0 0</pose>
            <velocity>0 0 0 0 -0 0</velocity>
            <acceleration>0 0 0 0 -0 0</acceleration>
            <wrench>0 0 0 0 -0 0</wrench>
          </link>
        </model>
        <model name='cafe_table'>
          <pose frame=''>-5 0 0 0 -0 0</pose>
          <scale>1 1 1</scale>
          <link name='link'>
            <pose frame=''>-5 0 0 0 -0 0</pose>
            <velocity>0 0 0 0 -0 0</velocity>
            <acceleration>0 0 0 0 -0 0</acceleration>
            <wrench>0 0 0 0 -0 0</wrench>
          </link>
        </model>
        <model name='cart_front_steer'>
          <pose frame=''>-8 -8.5977 0 0 -0 0</pose>
          <scale>1 1 1</scale>
          <link name='chassis'>
            <pose frame=''>-8 -8.5977 0.15 0 -0 0</pose>
            <velocity>0 0 0 0 -0 0</velocity>
            <acceleration>0 0 0 0 -0 0</acceleration>
            <wrench>0 0 0 0 -0 0</wrench>
          </link>
          <link name='wheel_front_left'>
            <pose frame=''>-7.5 -8.2997 0.15 -1.5708 -0.087266 0</pose>
            <velocity>0 0 0 0 -0 0</velocity>
            <acceleration>0 0 0 0 -0 0</acceleration>
            <wrench>0 0 0 0 -0 0</wrench>
          </link>
          <link name='wheel_front_right'>
            <pose frame=''>-7.5 -8.8957 0.15 -1.5708 -0.087266 0</pose>
            <velocity>0 0 0 0 -0 0</velocity>
            <acceleration>0 0 0 0 -0 0</acceleration>
            <wrench>0 0 0 0 -0 0</wrench>
          </link>
          <link name='wheel_rear_left'>
            <pose frame=''>-8.5 -8.2997 0.15 -1.5708 0 0</pose>
            <velocity>0 0 0 0 -0 0</velocity>
            <acceleration>0 0 0 0 -0 0</acceleration>
            <wrench>0 0 0 0 -0 0</wrench>
          </link>
          <link name='wheel_rear_right'>
            <pose frame=''>-8.5 -8.8957 0.15 -1.5708 0 0</pose>
            <velocity>0 0 0 0 -0 0</velocity>
            <acceleration>0 0 0 0 -0 0</acceleration>
            <wrench>0 0 0 0 -0 0</wrench>
          </link>
        </model>
        <model name='cart_rigid_suspension'>
          <pose frame=''>-6 -8.46967 0 0 -0 0</pose>
          <scale>1 1 1</scale>
          <link name='chassis'>
            <pose frame=''>-6 -8.46967 0.15 0 -0 0</pose>
            <velocity>0 0 0 0 -0 0</velocity>
            <acceleration>0 0 0 0 -0 0</acceleration>
            <wrench>0 0 0 0 -0 0</wrench>
          </link>
          <link name='wheel_front_left'>
            <pose frame=''>-5.5 -8.17167 0.15 -1.5708 0 0</pose>
            <velocity>0 0 0 0 -0 0</velocity>
            <acceleration>0 0 0 0 -0 0</acceleration>
            <wrench>0 0 0 0 -0 0</wrench>
          </link>
          <link name='wheel_front_right'>
            <pose frame=''>-5.5 -8.76767 0.15 -1.5708 0 0</pose>
            <velocity>0 0 0 0 -0 0</velocity>
            <acceleration>0 0 0 0 -0 0</acceleration>
            <wrench>0 0 0 0 -0 0</wrench>
          </link>
          <link name='wheel_rear_left'>
            <pose frame=''>-6.5 -8.17167 0.15 -1.5708 0 0</pose>
            <velocity>0 0 0 0 -0 0</velocity>
            <acceleration>0 0 0 0 -0 0</acceleration>
            <wrench>0 0 0 0 -0 0</wrench>
          </link>
          <link name='wheel_rear_right'>
            <pose frame=''>-6.5 -8.76767 0.15 -1.5708 0 0</pose>
            <velocity>0 0 0 0 -0 0</velocity>
            <acceleration>0 0 0 0 -0 0</acceleration>
            <wrench>0 0 0 0 -0 0</wrench>
          </link>
        </model>
        <model name='turtlebot'>
          <pose frame=''>-1 1 0 0 -0 0</pose>
          <scale>1 1 1</scale>
          <link name='create::base'>
            <pose frame=''>-1 1 0 0 -0 0</pose>
            <velocity>0 0 0 0 -0 0</velocity>
            <acceleration>0 0 0 0 -0 0</acceleration>
            <wrench>0 0 0 0 -0 0</wrench>
          </link>
          <link name='create::left_wheel'>
            <pose frame=''>-1 1.13 0.032 0 -0 0</pose>
            <velocity>0 0 0 0 -0 0</velocity>
            <acceleration>0 0 0 0 -0 0</acceleration>
            <wrench>0 0 0 0 -0 0</wrench>
          </link>
          <link name='create::right_wheel'>
            <pose frame=''>-1 0.87 0.032 0 -0 0</pose>
            <velocity>0 0 0 0 -0 0</velocity>
            <acceleration>0 0 0 0 -0 0</acceleration>
            <wrench>0 0 0 0 -0 0</wrench>
          </link>
          <link name='kinect::link'>
            <pose frame=''>-1.0871 1 0.303857 0 -0 0</pose>
            <velocity>0 0 0 0 -0 0</velocity>
            <acceleration>0 0 0 0 -0 0</acceleration>
            <wrench>0 0 0 0 -0 0</wrench>
          </link>
          <link name='rack'>
            <pose frame=''>-1 1 0 0 -0 0</pose>
            <velocity>0 0 0 0 -0 0</velocity>
            <acceleration>0 0 0 0 -0 0</acceleration>
            <wrench>0 0 0 0 -0 0</wrench>
          </link>
        </model>
        <model name='turtlebot_0'>
          <pose frame=''>0.43159 0 0 0 -0 0</pose>
          <scale>1 1 1</scale>
          <link name='create::base'>
            <pose frame=''>0.43159 0 0 0 -0 0</pose>
            <velocity>0 0 0 0 -0 0</velocity>
            <acceleration>0 0 0 0 -0 0</acceleration>
            <wrench>0 0 0 0 -0 0</wrench>
          </link>
          <link name='create::left_wheel'>
            <pose frame=''>0.43159 0.13 0.032 0 -0 0</pose>
            <velocity>0 0 0 0 -0 0</velocity>
            <acceleration>0 0 0 0 -0 0</acceleration>
            <wrench>0 0 0 0 -0 0</wrench>
          </link>
          <link name='create::right_wheel'>
            <pose frame=''>0.43159 -0.13 0.032 0 -0 0</pose>
            <velocity>0 0 0 0 -0 0</velocity>
            <acceleration>0 0 0 0 -0 0</acceleration>
            <wrench>0 0 0 0 -0 0</wrench>
          </link>
          <link name='kinect::link'>
            <pose frame=''>0.344492 0 0.303857 0 -0 0</pose>
            <velocity>0 0 0 0 -0 0</velocity>
            <acceleration>0 0 0 0 -0 0</acceleration>
            <wrench>0 0 0 0 -0 0</wrench>
          </link>
          <link name='rack'>
            <pose frame=''>0.43159 0 0 0 -0 0</pose>
            <velocity>0 0 0 0 -0 0</velocity>
            <acceleration>0 0 0 0 -0 0</acceleration>
            <wrench>0 0 0 0 -0 0</wrench>
          </link>
        </model>
      </model>
      <model name='ground_plane'>
        <pose frame=''>0 0 0 0 -0 0</pose>
        <scale>1 1 1</scale>
        <link name='link'>
          <pose frame=''>0 0 0 0 -0 0</pose>
          <velocity>0 0 0 0 -0 0</velocity>
          <acceleration>0 0 0 0 -0 0</acceleration>
          <wrench>0 0 0 0 -0 0</wrench>
        </link>
      </model>
      <light name='sun'>
        <pose frame=''>0 0 10 0 -0 0</pose>
      </light>
    </state>
    <gui fullscreen='0'>
      <camera name='user_camera'>
        <pose frame=''>4.1824 -23.6637 24.9901 -0 0.727643 1.721</pose>
        <view_controller>orbit</view_controller>
        <projection_type>perspective</projection_type>
      </camera>
    </gui>
  </world>
</sdf>
